Workbook

Sheet VAT Schedule
A2: Shirefolk, Inc
A3: YEAR 2025
B4: Taz-Exempt Sales | C4: Vatable-Sales | D4: Vat on Sales (Output Tax) | E4: Input Tax Carried Over | F4: VAT on Purchases (Goods Not Qual for Input Tax) | G4: VAT on Purchases (Services Not Qualified for Input Tax) | H4: Purchases Capital Goods | I4: Purchases of Goods Other than Capital Goods | J4: Purchases of Services | K4: Vat on Purchases of Capital Goods (Input Tax) | L4: Allowable Vat on Purchases of Capital Goods More Than 1M (Input Tax) | M4: Vat on Purchases of Goods other than Capital Goods & Services (Input Tax) | N4: Total Vat on Purchases (Input Tax) | O4: VAT Payable | P4: in eBIR Form | Q4: difference | S4: Amount Filed | T4: Date Filed | U4: Date Paid | V4: SLSP
A6: Beg. Bal. | O6: 0
A7: Q1 2025 | B7: 0 | C7: 5011457.3 | D7: =C7*0.12 -> 601374.87 | E7: 0 | F7: 33374.37 | G7: =SUM('Xero Purchases S'!H13) -> 0 | H7: 7714.29 | I7: 225614.24 | J7: 1751892.4 | K7: =H7*0.12 -> 925.7148 | L7: =401500.9-355637.67 -> 45863.23 | M7: =SUM(I7:J7)*0.12 -> 237300.8 | N7: =SUM(K7:M7) -> 284089.74 | O7: =$D7+$E7-$N7 -> 317285.13
A8: `1st Quarter | B8: =SUM(B7) -> 0 | C8: =SUM(C7) -> 5011457.3 | D8: =C8*0.12 -> 601374.87 | E8: =O6 -> 0 | F8: =SUM(F7) -> 33374.37 | G8: =SUM(G7) -> 0 | H8: =SUM(H7) -> 7714.29 | I8: =SUM(I7) -> 225614.24 | J8: =SUM(J7) -> 1751892.4 | K8: =SUM(K7) -> 925.7148 | L8: =SUM(L7) -> 45863.23 | M8: =SUM(M7) -> 237300.8 | N8: =SUM(N7) -> 284089.74 | O8: =$D8+$E8-$N8 -> 317285.13
A11: Beg. Bal. | O11: 0
A12: January | C12: =SUM('Xero Sales'!G18:G292,'Xero Sales'!G828,'Xero Sales'!G834,'Xero Sales'!G855) -> 2474960.2 | D12: =C12*0.12 -> 296995.22 | E12: 0 | F12: =SUM('Xero Purchases G'!H11:H14) -> 630 | G12: =SUM('Xero Purchases S'!H15:H17) -> 580 | H12: =SUM(0) -> 0 | I12: =SUM('Xero Purchases G'!H40:H56) -> 23768.89 | J12: =SUM('Xero Purchases S'!H11,'Xero Purchases S'!H29:H51) -> 450457.51 | K12: =H12*0.12 -> 0 | L12: ='Schedule of CG Input Tax'!R15 -> 7643.8703 | M12: =SUM(I12:J12)*0.12 -> 56907.168 | N12: =SUM(K12:M12) -> 64551.038 | O12: =$D12+$E12-$N12 -> 232444.19
A13: February | B13: 0 | C13: =SUM('Xero Sales'!G294:G536)-SUM('Xero Sales'!G809,'Xero Sales'!G823) -> 1080016.4 | D13: =C13*0.12 -> 129601.97 | E13: 0 | F13: =SUM('Xero Purchases G'!H16:H18) -> 436.07 | G13: =SUM('Xero Purchases S'!H19:H20) -> 10400 | H13: =SUM(0) -> 0 | I13: =SUM('Xero Purchases G'!H58:H77) -> 44442.85 | J13: =SUM('Xero Purchases S'!H53:H70) -> 458377.52 | K13: =H13*0.12 -> 0 | L13: ='Schedule of CG Input Tax'!S15 -> 7643.8703 | M13: =SUM(I13:J13)*0.12 -> 60338.444 | N13: =SUM(K13:M13) -> 67982.315 | O13: =$D13+$E13-$N13 -> 61619.654
A14: March | B14: 0 | C14: =SUM('Xero Sales'!G538:G796)-'Xero Sales'!G798 -> 1366349.4 | D14: =C14*0.12 -> 163961.93 | E14: 0 | F14: =SUM('Xero Purchases G'!H20:H36) -> 3178.3 | G14: =SUM('Xero Purchases S'!H22:H25) -> 18300 | H14: =SUM(0) -> 0 | I14: =SUM('Xero Purchases G'!H79:H116) -> 157402.49 | J14: =SUM('Xero Purchases S'!H72:H109) -> 843057.39 | K14: =H14*0.12 -> 0 | L14: ='Schedule of CG Input Tax'!T15 -> 7643.8703 | M14: =SUM(I14:J14)*0.12 -> 120055.19 | N14: =SUM(K14:M14) -> 127699.06 | O14: =$D14+$E14-$N14 -> 36262.877
A15: `1st Quarter Amended | B15: =SUM(B12:B14) -> 0 | C15: =SUM(C12:C14) -> 4921326 | D15: =C15*0.12 -> 590559.12 | E15: =O11 -> 0 | F15: =SUM(F12:F14) -> 4244.37 | G15: =SUM(G12:G14) -> 29280 | H15: =SUM(H12:H14) -> 0 | I15: =SUM(I12:I14) -> 225614.23 | J15: =SUM(J12:J14) -> 1751892.4 | K15: =SUM(K12:K14) -> 0 | L15: =SUM(L12:L14) -> 22931.611 | M15: =SUM(M12:M14) -> 237300.8 | N15: =SUM(N12:N14) -> 260232.41 | O15: =$D15+$E15-$N15 -> 330326.72 | P15: =O15/SUM(B15:C15) -> 0.067121486
C16: =C15-'Xero Sales'!M844 -> 0.64714287 | I16: =I15-'Xero Purchases G'!H117 -> 0 | J16: =J15-'Xero Purchases S'!H110-'Xero Purchases S'!H12 -> -1.0244605e-10
A18: April | B18: ='Xero Sales'!G13 -> 37500 | C18: 1548215.6 | D18: =C18*12% -> 185785.88 | E18: 0 | F18: =SUM('Xero Purchases G'!H133:H156) -> 19678.8 | G18: =SUM('Xero Purchases S'!H126) -> 1921.32 | H18: 0 | I18: =SUM('Xero Purchases G'!H184:H193) -> 13107.64 | J18: =SUM('Xero Purchases S'!H133:H159) -> 523840.2 | K18: =H18*0.12 -> 0 | L18: ='Schedule of CG Input Tax'!U15 -> 7643.8703 | M18: =(SUM(I18:J18)*0.12) -> 64433.741 | N18: =SUM(K18:M18) -> 72077.611 | O18: =$D18+$E18-$N18 -> 113708.27
A19: May | B19: 0 | C19: =SUM('Xero Sales'!G1174:G1448,'Xero Sales'!G1722) -> 1339480.4 | D19: =C19*12% -> 160737.65 | E19: 0 | F19: =SUM('Xero Purchases G'!H158:H175) -> 2466 | G19: =SUM('Xero Purchases S'!J128:J129) -> 0 | H19: 0 | I19: =SUM('Xero Purchases G'!H195:H209) -> 21831.75 | J19: =SUM('Xero Purchases S'!H161:H184) -> 468577.49 | K19: =H19*0.12 -> 0 | L19: ='Schedule of CG Input Tax'!V15 -> 7643.8703 | M19: =(SUM(I19:J19)*0.12) -> 58849.109 | N19: =SUM(K19:M19) -> 66492.979 | O19: =$D19+$E19-$N19 -> 94244.673
A20: June | B20: 0 | C20: =SUM('Xero Sales'!G1450:G1713) -> 1098895.4 | D20: =C20*12% -> 131867.45 | E20: 0 | F20: =SUM('Xero Purchases G'!H177:H180) -> 755.4 | G20: 0 | H20: 0 | I20: =SUM('Xero Purchases G'!H211:H228) -> 23033.48 | J20: =SUM('Xero Purchases S'!H186:H197) -> 350529.27 | K20: =H20*0.12 -> 0 | L20: ='Schedule of CG Input Tax'!W15 -> 7643.8703 | M20: =(SUM(I20:J20)*0.12) -> 44827.53 | N20: =SUM(K20:M20) -> 52471.4 | O20: =$D20+$E20-$N20 -> 79396.053
A21: 2nd Quarter | B21: =SUM(B18:B20) -> 37500 | C21: =SUM(C18:C20) -> 3986591.5 | D21: =C21*0.12 -> 478390.98 | E21: =E18 -> 0 | F21: =SUM(F18:F20) -> 22900.2 | G21: =SUM(G18:G20) -> 1921.32 | H21: =SUM(H18:H20) -> 0 | I21: =SUM(I18:I20) -> 57972.87 | J21: =SUM(J18:J20) -> 1342947 | K21: =SUM(K18:K20) -> 0 | L21: =SUM(L18:L20) -> 22931.611 | M21: =SUM(M18:M20) -> 168110.38 | N21: =SUM(K21:M21) -> 191041.99 | O21: =D21+E21-N21 -> 287348.99 | P21: =O21/SUM(B21:C21) -> 0.071407171
C22: =C21-SI!G2741 -> 0.67071429 | D22: =D21-SI!H2741 -> 0.080485715
A23: July | B23: 0 | C23: =SUM('Xero Sales'!G1757:G2039)-SUM('Xero Sales'!G2046:G2051) -> 1525930.2 | D23: =C23*12% -> 183111.63 | E23: 0 | F23: =SUM('Xero Purchases G'!G454:G465) -> 0 | G23: =SUM('Xero Purchases S'!H213) -> 800 | H23: =SUM('Xero Purchases G'!H245:H249) -> 1820.53 | I23: =SUM('Xero Purchases G'!H253:H267) -> 10331.11 | J23: =SUM('Xero Purchases S'!H217:H230) -> 381222.43 | K23: =H23*0.12 -> 218.4636 | L23: ='Schedule of CG Input Tax'!X15 -> 7643.8703 | M23: =(SUM(I23:J23)*0.12) -> 46986.425 | N23: =SUM(K23:M23) -> 54848.759 | O23: =$D23+$E23-$N23 -> 128262.87
A24: August | B24: 0 | C24: =SI!G2743 -> 1316048.3 | D24: =C24*12% -> 157925.8 | E24: 0 | F24: =SUM('Xero Purchases G'!G467:G482) -> 0 | G24: =SUM('Xero Purchases S'!G237:G241) -> 0 | H24: 0 | I24: ='Xero Purchases G'!H282 -> 7200 | J24: =SUM('Xero Purchases S'!H245:H263) -> 539658.21 | K24: =H24*0.12 -> 0 | L24: ='Schedule of CG Input Tax'!Y15 -> 7643.8703 | M24: =(SUM(I24:J24)*0.12) -> 65622.985 | N24: =SUM(K24:M24) -> 73266.855 | O24: =$D24+$E24-$N24 -> 84658.946
A25: September | D25: =C25*12% -> 0 | E25: 0 | F25: =SUM('Xero Purchases G'!G484:G494) -> 0 | G25: =SUM('Xero Purchases S'!G243:G244) -> 0 | H25: 0 | I25: =SUM('Xero Purchases G'!H537:H551) -> 0 | J25: =SUM('Xero Purchases S'!H302:H332) -> 0 | K25: =H25*0.12 -> 0 | L25: 0 | M25: =(SUM(I25:J25)*0.12) -> 0 | N25: =SUM(K25:M25) -> 0 | O25: =$D25+$E25-$N25 -> 0
A26: 3rd Quarter | B26: =SUM(B23:B25) -> 0 | C26: =SUM(C23:C25) -> 2841978.6 | D26: =C26*0.12 -> 341037.43 | E26: =E23 -> 0 | F26: =SUM(F23:F25) -> 0 | G26: =SUM(G23:G25) -> 800 | H26: =SUM(H23:H25) -> 1820.53 | I26: =SUM(I23:I25) -> 17531.11 | J26: =SUM(J23:J25) -> 920880.64 | K26: =SUM(K23:K25) -> 218.4636 | L26: =SUM(L23:L25) -> 15287.741 | M26: =SUM(M23:M25) -> 112609.41 | N26: =SUM(K26:M26) -> 128115.61 | O26: =D26+E26-N26 -> 212921.81
A28: Oct | D28: =C28*12% -> 0 | K28: =H28*0.12 -> 0 | M28: =(SUM(I28:J28)*0.12) -> 0 | N28: =SUM(K28:M28) -> 0 | O28: =$D28+$E28-$N28 -> 0
A29: Nov | D29: =C29*12% -> 0 | E29: =IF($P28<0,$P28,"") | G29: 0 | H29: 0 | K29: =H29*0.12 -> 0 | M29: =(SUM(I29:J29)*0.12) -> 0 | N29: =SUM(K29:M29) -> 0 | O29: =$D29+$E29-$N29 -> 0
A30: Dec | D30: =C30*12% -> 0 | E30: =IF($P29<0,$P29,"") | K30: =H30*0.12 -> 0 | M30: =(SUM(I30:J30)*0.12) -> 0 | N30: =SUM(K30:M30) -> 0 | O30: =$D30+$E30-$N30 -> 0
A31: 4th Quarter | B31: =SUM(B28:B30) -> 0 | C31: =SUM(C28:C30) -> 0 | D31: =C31*0.12 -> 0 | E31: =E28 | F31: =SUM(F28:F30) -> 0 | G31: =SUM(G28:G30) -> 0 | H31: =SUM(H28:H30) -> 0 | I31: =SUM(I28:I30) -> 0 | J31: =SUM(J28:J30) -> 0 | K31: =SUM(K28:K30) -> 0 | L31: =SUM(L28:L30) -> 0 | M31: =SUM(M28:M30) -> 0 | N31: =SUM(N28:N30) -> 0 | O31: =D31+E31-N31 -> 0
A33: Year Total | B33: =B8+B21+B26+B31 -> 37500 | C33: =C8+C21+C26+C31 -> 11840027 | D33: =D8+D21+D26+D31 -> 1420803.3 | E33: =E8+E21+E26+E31 -> 0 | F33: =F8+F21+F26+F31 -> 56274.57 | G33: =G8+G21+G26+G31 -> 2721.32 | H33: =H8+H21+H26+H31 -> 9534.82 | I33: =I8+I21+I26+I31 -> 301118.22 | ... N33: =N8+N21+N26+N31 -> 603247.35 | O33: =O31 -> 0

Sheet SI
B1: Date | C1: Xero Inv. No. | D1: Client Name | E1: OR Amount | F1: Description | G1: Mode of Payment | H1: Cash / Check Deposit | I1: Remarks | J1: Type of Service | K1: GROSS | L1: CWT | M1: TOTAL | N1: Checking | O1: EWT | P1: CC Fee | Q1: Net Amount | R1: Checking | U1: NATURE | X1: GROSS AMOUNT | Y1: NET AMOUNT | Z1: VAT AMOUNT | AB1: GROSS AMOUNT | AC1: NET AMOUNT | AD1: VAT AMOUNT
A2: 1201 | B2: 45659 | C2: INV-10151 | D2: Gabby Ortega (Gabriela Ortega) | E2: 550 | F2: Whole Day Flypass | G2: Gcash QR Standee | H2: UBP | J2: Walk-Ins | K2: =E2 -> 550 | L2: 0 | M2: =K2-L2 -> 550 | N2: =E2-M2 -> 0 | P2: 13.4 | Q2: =E2-P2 -> 536.6 | X2: =E2 -> 550 | Y2: =X2/1.12 -> 491.07143 | Z2: =Y2*0.12 -> 58.928571 | AB2: 550 | AC2: 491.07143 | AD2: 58.928571 | AF2: =AC2-Y2 -> 0
A3: 1202 | B3: 45659 | C3: INV-10146 | D3: Aguilar IT Solutions | E3: 3000 | F3: Virtual Office,Dec 24, 2024 - Jan 23, 2025 | G3: Check | H3: UBP | I3: Eastwest Bank 0001545556 | J3: Virtual Office | K3: =E3 -> 3000 | L3: 0 | M3: =K3-L3 -> 3000 | N3: =E3-M3 -> 0 | X3: =E3 -> 3000 | Y3: =X3/1.12 -> 2678.5714 | Z3: =Y3*0.12 -> 321.42857 | AB3: 3000 | AC3: 2678.5714 | AD3: 321.42857 | AF3: =AC3-Y3 -> 0
A4: 1203 | B4: 45659 | C4: INV-10152 | D4: Paulwil Martin | E4: 400 | F4: 3 hour Flypass and 1 hour extension | G4: Gcash QR Standee | H4: UBP | J4: Walk-Ins | K4: =E4 -> 400 | L4: 0 | M4: =K4-L4 -> 400 | N4: =E4-M4 -> 0 | P4: 9.75 | Q4: =E4-P4 -> 390.25 | X4: =E4 -> 400 | Y4: =X4/1.12 -> 357.14286 | Z4: =Y4*0.12 -> 42.857143 | AB4: 400 | AC4: 357.14286 | AD4: 42.857143 | AF4: =AC4-Y4 -> 0
A5: 1204 | B5: 45659 | C5: INV-10147 | D5: CP-DC Development Corporation | E5: 3000 | F5: Virtual Office,Dec 24, 2024 - Jan 23, 2025 | G5: Check | H5: UBP | I5: Chinabank 0001902944 | J5: Virtual Office | K5: =E5 -> 3000 | L5: 0 | M5: =K5-L5 -> 3000 | N5: =E5-M5 -> 0 | X5: =E5 -> 3000 | Y5: =X5/1.12 -> 2678.5714 | Z5: =Y5*0.12 -> 321.42857 | AB5: 3000 | AC5: 2678.5714 | AD5: 321.42857 | AE5: 2024 SALES | AF5: =AC5-Y5 -> 0
A6: 1205 | D6: CANCELLED | K6: =E6 | L6: 0 | M6: =K6-L6 -> 0 | N6: =E6-M6 -> 0 | AF6: =AC6-Y6 -> 0
A7: 1206 | B7: 45659 | C7: INV-10166 | D7: Vipre Security Group Philippines Inc. | E7: 86650.89 | F7: Voyager 3 rent, January 2025 rent | G7: Check | H7: UBP | J7: Virtual Office | K7: 90700 | L7: =K7/1.12*0.05 -> 4049.1071 | M7: =K7-L7 -> 86650.893 | N7: =E7-M7 -> -0.0028571429 | X7: =E7 -> 86650.89 | Y7: =X7/1.12 -> 77366.866 | Z7: =Y7*0.12 -> 9284.0239 | AB7: 90700 | AC7: 80982.143 | AD7: 9717.8571 | AF7: =AC7-Y7 -> 3615.2768
A8: 1207 | B8: 45659 | C8: INV-10009 | D8: Bon Conseil Realty OPC | E8: 2866.07 | F8: Virtual Office, Dec 24, 2024 to Jan 23, 2025 | G8: Bank Transfer | H8: UBP | I8: UB3673112 | J8: Virtual Office | K8: 3000 | L8: =K8/1.12*0.05 -> 133.92857 | M8: =K8-L8 -> 2866.0714 | N8: =E8-M8 -> -0.0014285714 | X8: =E8 -> 2866.07 | Y8: =X8/1.12 -> 2558.9911 | Z8: =Y8*0.12 -> 307.07893 | AB8: 3000 | AC8: =AB8/1.12 -> 2678.5714 | AD8: =AC8*12% -> 321.42857 | AE8: 45627 | AF8: =AC8-Y8 -> 119.58036
A9: 1208 | B9: 45659 | C9: INV-10181 | D9: Tristan San Buenaventura | E9: 1544 | F9: Astra 1, 3:30pm to 5:30pm and Printing 36xP4 | G9: Gcash QR Standee | H9: UBP | J9: Meeting Rooms | K9: =E9 -> 1544 | L9: 0 | M9: =K9-L9 -> 1544 | N9: =E9-M9 -> 0 | P9: 37.62 | Q9: =E9-P9 -> 1506.38 | X9: =E9 -> 1544 | Y9: =X9/1.12 -> 1378.5714 | Z9: =Y9*0.12 -> 165.42857 | AB9: 1544 | AC9: 1378.5714 | AD9: 165.42857 | AF9: =AC9-Y9 -> 0
A10: 1209 | B10: 45659 | C10: INV-10153 | D10: AF Vista City Inc | E10: 8980.36 | F10: Astra 1, Dec 26-27, 2024, 10 am to 5pm | G10: Check | H10: UBP | I10: BDO 0000174186 | J10: Meeting Rooms | K10: 9400 | L10: =K10/1.12*0.05 -> 419.64286 | M10: =K10-L10 -> 8980.3571 | N10: =E10-M10 -> 0.0028571429 | X10: =K10 -> 9400 | Y10: =X10/1.12 -> 8392.8571 | Z10: =Y10*0.12 -> 1007.1429 | AB10: 9400 | AC10: 8392.8571 | AD10: 1007.1429 | AF10: =AC10-Y10 -> 0
A11: 1210 | B11: 45660 | C11: INV-10171 | D11: Mylene Padua | E11: 300 | F11: 3 hour Flypass | G11: Cash | K11: =E11 -> 300 | L11: 0 | M11: =K11-L11 -> 300 | N11: =E11-M11 -> 0 | X11: =E11 -> 300 | Y11: =X11/1.12 -> 267.85714 | Z11: =Y11*0.12 -> 32.142857 | AB11: 300 | AC11: 267.85714 | AD11: 32.142857 | AF11: =AC11-Y11 -> 0
A12: 1211 | B12: 45660 | C12: INV-10185 | D12: Plebeian B Medina | E12: 2100 | F12: Rocket Room, 9 am to 12pm | G12: Maya Card | H12: UBP | J12: Meeting Rooms | K12: =E12 -> 2100 | L12: 0 | M12: =K12-L12 -> 2100 | N12: =E12-M12 -> 0 | P12: 68.96 | Q12: =E12-P12 -> 2031.04 | X12: =E12 -> 2100 | Y12: =X12/1.12 -> 1875 | Z12: =Y12*0.12 -> 225 | AB12: 2100 | AC12: 1875 | AD12: 225 | AF12: =AC12-Y12 -> 0
A13: 1212 | B13: 45660 | C13: INV-9977 | D13: Bon Conseil Realty OPC | E13: 2200.45 | F13: Locker rental, Dec 3, 2024 to Jul 23, 2025 | G13: Bank Transfer | H13: UBP | J13: Add Ons | K13: 2303.28 | L13: =K13/1.12*0.05 -> 102.825 | M13: =K13-L13 -> 2200.455 | N13: =E13-M13 -> -0.005 | X13: =K13 -> 2303.28 | Y13: =X13/1.12 -> 2056.5 | Z13: =Y13*0.12 -> 246.78 | AB13: 2303.28 | AC13: 2056.5 | AD13: 246.78 | AE13: 45627 | AF13: =AC13-Y13 -> 0
A14: 1213 | B14: 45660 | C14: INV-10173 | D14: Christina Paruli | E14: 1400 | F14: Rocket Room Jan 3, 2025, 1pm to 3pm | G14: AR 795 Bank Transfer BPI (1400) Cash (700) | H14: MBTC | J14: Meeting Rooms | K14: =E14 -> 1400 | L14: 0 | M14: =K14-L14 -> 1400 | N14: =E14-M14 -> 0 | X14: =E14 -> 1400 | Y14: =X14/1.12 -> 1250 | Z14: =Y14*0.12 -> 150 | AB14: 1400 | AC14: 1250 | AD14: 150 | AF14: =AC14-Y14 -> 0
A15: 1214 | B15: 45660 | C15: INV-10174/INV-10176/INV-10177/INV-10178 | D15: Nix - N.T.B. Hair and Make up Services | E15: 34200 | F15: Event Space, Mar 1, May 24, Aug 30, Nov 22, 2025 - 9 am to 5pm | G15: Bank Transfer | H15: BPI | I15: 4348 | J15: Events | K15: =E15 -> 34200 | L15: 0 | M15: =K15-L15 -> 34200 | N15: =E15-M15 -> 0 | X15: =E15 -> 34200 | Y15: =X15/1.12 -> 30535.714 | Z15: =Y15*0.12 -> 3664.2857 | AB15: 34200 | AC15: 30535.714 | AD15: 3664.2857 | AE15: 8550 Xero | AF15: =AC15-Y15 -> 0
A16: 1215 | B16: 45660 | D16: Altech Vialab Inc. | E16: 25680 | F16: Office Suite 2 rent, Jan 1 - 31, 2025 (w/ 20% disc) | G16: Check | H16: UBP | I16: UBP 2002750714 | J16: Private Office | K16: 26880 | L16: =K16/1.12*0.05 -> 1200 | M16: =K16-L16 -> 25680 | N16: =E16-M16 -> 0 | X16: =K16 -> 26880 | Y16: =X16/1.12 -> 24000 | Z16: =Y16*0.12 -> 2880 | AE16: CANCELLED SI | AF16: =AC16-Y16 -> -24000
A17: 1216 | B17: 45660 | D17: Primera Biosolutions, Inc. | E17: 25680 | F17: Office Suite 2 rent, Jan 1 - 31, 2025 (w/ 20% disc) | G17: Check | H17: UBP | I17: UBP 2002918897 | J17: Private Office | K17: 26880 | L17: =K17/1.12*0.05 -> 1200 | M17: =K17-L17 -> 25680 | N17: =E17-M17 -> 0 | X17: =K17 -> 26880 | Y17: =X17/1.12 -> 24000 | Z17: =Y17*0.12 -> 2880 | AE17: CANCELLED SI | AF17: =AC17-Y17 -> -24000
A18: 1217 | B18: 45660 | C18: INV-10154 | D18: Marketing Master IO OPC | E18: 42000 | F18: Virtual Office, Jan 1, 2025 to December 31, 2025 | G18: Bank Transfer | H18: UBP | I18: UB422332 | J18: Virtual Office | K18: =E18 -> 42000 | L18: 0 | M18: =K18-L18 -> 42000 | N18: =E18-M18 -> 0 | X18: =E18 -> 42000 | Y18: =X18/1.12 -> 37500 | Z18: =Y18*0.12 -> 4500 | AB18: 42000 | AC18: 37500 | AD18: 4500 | AF18: =AC18-Y18 -> 0
A19: 1218 | B19: 45660 | C19: INV-10162 | D19: Megaluck Prime Solutions Inc | E19: 15000 | F19: Use Of Address, Jan 1, 2025 to December 31, 2025 | G19: Check | H19: UBP | I19: BDO 40620 | J19: Virtual Office | K19: =E19 -> 15000 | L19: 0 | M19: =K19-L19 -> 15000 | N19: =E19-M19 -> 0 | X19: =E19 -> 15000 | Y19: =X19/1.12 -> 13392.857 | Z19: =Y19*0.12 -> 1607.1429 | AB19: 15000 | AC19: 13392.857 | AD19: 1607.1429 | AF19: =AC19-Y19 -> 0
A20: 1219 | B20: 45660 | C20: INV-10167 | D20: Blue Point Properties Inc | E20: 1375 | F20: Use Of Address, Dec 29, 2024 to January 28, 2025 | G20: Check | H20: UBP | I20: Maybank 5022 | J20: Virtual Office | K20: =E20 -> 1375 | L20: 0 | M20: =K20-L20 -> 1375 | N20: =E20-M20 -> 0 | X20: =E20 -> 1375 | Y20: =X20/1.12 -> 1227.6786 | Z20: =Y20*0.12 -> 147.32143 | AB20: 1375 | AC20: 1227.6786 | AD20: 147.32143 | AE20: Dec sales | AF20: =AC20-Y20 -> 0
A21: 1220 | B21: 45660 | C21: INV-10168 | D21: Birch Registries Inc | E21: 1250 | F21: Use Of Address, Jan 2, 2025 to February 1, 2025 | G21: Check | H21: UBP | I21: BPI 1000162435 | J21: Virtual Office | K21: =E21 -> 1250 | L21: 0 | M21: =K21-L21 -> 1250 | N21: =E21-M21 -> 0 | X21: =E21 -> 1250 | Y21: =X21/1.12 -> 1116.0714 | Z21: =Y21*0.12 -> 133.92857 | AB21: 1250 | AC21: 1116.0714 | AD21: 133.92857 | AF21: =AC21-Y21 -> 0
A22: 1221 | B22: 45660 | C22: INV-10169 | D22: JFAQ Enterprise | E22: 1250 | F22: Use Of Address, Jan 1 - 31, 2025 | G22: Check | H22: UBP | I22: Eastwest Bank 0001567802 | J22: Virtual Office | K22: =E22 -> 1250 | L22: 0 | M22: =K22-L22 -> 1250 | N22: =E22-M22 -> 0 | X22: =E22 -> 1250 | Y22: =X22/1.12 -> 1116.0714 | Z22: =Y22*0.12 -> 133.92857 | AB22: 1250 | AC22: 1116.0714 | AD22: 133.92857 | AF22: =AC22-Y22 -> 0
A23: 1222 | B23: 45660 | C23: INV-10170 | D23: Prime Accounting and Consultancy Inc | E23: 955.36 | F23: Use Of Address, Jan 2, 2025 to February 1, 2025 | G23: Check | H23: UBP | I23: Chinabank 0000057687 | J23: Walk-Ins | K23: 1000 | L23: =K23/1.12*0.05 -> 44.642857 | M23: =K23-L23 -> 955.35714 | N23: =E23-M23 -> 0.0028571429 | X23: =E23 -> 955.36 | Y23: =X23/1.12 -> 853 | Z23: =Y23*0.12 -> 102.36 | AB23: 1000 | AC23: =AB23/1.12 -> 892.85714 | AD23: =AC23*12% -> 107.14286 | AF23: =AC23-Y23 -> 39.857143
A24: 1223 | B24: 45660 | C24: INV-10179 | D24: Jejo Fish Farm | E24: 2600 | F24: Meeting room (Suite 6), 1pm to 5pm | G24: Cash | H24: MBTC | J24: Meeting Rooms | K24: =E24 -> 2600 | L24: 0 | M24: =K24-L24 -> 2600 | N24: =E24-M24 -> 0 | X24: =E24 -> 2600 | Y24: =X24/1.12 -> 2321.4286 | Z24: =Y24*0.12 -> 278.57143 | AB24: 2600 | AC24: 2321.4286 | AD24: 278.57143 | AF24: =AC24-Y24 -> 0
A25: 1224 | D25: CANCELLED | K25: =E25 | L25: 0 | M25: =K25-L25 -> 0 | N25: =E25-M25 -> 0 | AF25: =AC25-Y25 -> 0
A26: 1225 | B26: 45661 | C26: INV-10180 | D26: RLTY Property Corp | E26: 4000 | F26: Astra 1, 10 am to 3:30 pm | G26: Cash | H26: MBTC | J26: Meeting Rooms | K26: =E26 -> 4000 | L26: 0 | M26: =K26-L26 -> 4000 | N26: =E26-M26 -> 0 | X26: =E26 -> 4000 | Y26: =X26/1.12 -> 3571.4286 | Z26: =Y26*0.12 -> 428.57143 | AB26: 4000 | AC26: 3571.4286 | AD26: 428.57143 | AF26: =AC26-Y26 -> 0
A27: 1226 | B27: 45661 | C27: INV-10182 | D27: Zoi's Meat Town | E27: 2600 | F27: Astra 2, 11:30 am to 3:30 pm | G27: Maya Card | H27: UBP | J27: Meeting Rooms | K27: =E27 -> 2600 | L27: 0 | M27: =K27-L27 -> 2600 | N27: =E27-M27 -> 0 | P27: 85.38 | Q27: =E27-P27 -> 2514.62 | X27: =E27 -> 2600 | Y27: =X27/1.12 -> 2321.4286 | Z27: =Y27*0.12 -> 278.57143 | AB27: 2600 | AC27: 2321.4286 | AD27: 278.57143 | AF27: =AC27-Y27 -> 0
A28: 1227 | B28: 45661 | C28: INV-10183 | D28: Limuel Libres | E28: 300 | F28: Whole day Flypass (Student Discount) | G28: Cash | H28: MBTC | J28: Walk-Ins | K28: =E28 -> 300 | L28: 0 | M28: =K28-L28 -> 300 | N28: =E28-M28 -> 0 | X28: =E28 -> 300 | Y28: =X28/1.12 -> 267.85714 | Z28: =Y28*0.12 -> 32.142857 | AB28: 300 | AC28: 267.85714 | AD28: 32.142857 | AF28: =AC28-Y28 -> 0
A29: 1228 | B29: 45661 | C29: INV-10184 | D29: Fyre Talent Academy | E29: 2100 | F29: Rocket Room, 2pm to 5pm | G29: Bank Transfer | H29: BPI | J29: Meeting Rooms | K29: =E29 -> 2100 | L29: 0 | M29: =K29-L29 -> 2100 | N29: =E29-M29 -> 0 | X29: =E29 -> 2100 | Y29: =X29/1.12 -> 1875 | Z29: =Y29*0.12 -> 225 | AB29: 2100 | AC29: 1875 | AD29: 225 | AF29: =AC29-Y29 -> 0
A30: 1229 | B30: 45663 | C30: INV-10186 | D30: Therese Navales | E30: 550 | F30: Whole day Flypass | G30: Maya Card | H30: UBP | J30: Walk-Ins | K30: =E30 -> 550 | L30: 0 | M30: =K30-L30 -> 550 | N30: =E30-M30 -> 0 | P30: 18.06 | Q30: =E30-P30 -> 531.94 | X30: =E30 -> 550 | Y30: =X30/1.12 -> 491.07143 | Z30: =Y30*0.12 -> 58.928571 | AB30: 550 | AC30: 491.07143 | AD30: 58.928571 | AF30: =AC30-Y30 -> 0
A31: 1230 | B31: 45663 | C31: INV-10187 | D31: AB Mauri Philippines Inc | E31: 5000 | F31: Rocket Room, Jan 8, 2025, 8 am to 5 pm | G31: Cash | H31: MBTC | J31: Meeting Rooms | K31: =E31 -> 5000 | L31: 0 | M31: =K31-L31 -> 5000 | N31: =E31-M31 -> 0 | X31: =E31 -> 5000 | Y31: =X31/1.12 -> 4464.2857 | Z31: =Y31*0.12 -> 535.71429 | AB31: 5000 | AC31: 4464.2857 | AD31: 535.71429 | AF31: =AC31-Y31 -> 0
A32: 1231 | B32: 45663 | C32: INV-10188 | D32: Altech Vialab Inc. | E32: 25680 | F32: Office Suite 2 rent, Jan 1 - 31, 2025 (w/ 20% disc) | G32: Check | H32: UBP | I32: UBP 2002750714 | J32: Private Office | K32: 26880 | L32: =K32/1.12*0.05 -> 1200 | M32: =K32-L32 -> 25680 | N32: =E32-M32 -> 0 | X32: =K32 -> 26880 | Y32: =X32/1.12 -> 24000 | Z32: =Y32*0.12 -> 2880 | AB32: 26880 | AC32: 24000 | AD32: 2880 | AF32: =AC32-Y32 -> 0
A33: 1232 | B33: 45663 | C33: INV-10189 | D33: Primera Biosolutions, Inc. | E33: 25680 | F33: Office Suite 2 rent, Jan 1 - 31, 2025 (w/ 20% disc) | G33: Check | H33: UBP | I33: UBP 2002918897 | J33: Private Office | K33: 26880 | L33: =K33/1.12*0.05 -> 1200 | M33: =K33-L33 -> 25680 | N33: =E33-M33 -> 0 | X33: =K33 -> 26880 | Y33: =X33/1.12 -> 24000 | Z33: =Y33*0.12 -> 2880 | AB33: 26880 | AC33: 24000 | AD33: 2880 | AF33: =AC33-Y33 -> 0
A34: 1233 | B34: 45663 | C34: INV-10190 | D34: Werner Access Products Philippines Inc | E34: 18000 | F34: Apollo 4&5, Jan 6&20,2025, 8am to 4pm | G34: Maya Card | H34: UBP | J34: Meeting Rooms | K34: =E34 -> 18000 | L34: 0 | M34: =K34-L34 -> 18000 | N34: =E34-M34 -> 0 | P34: 591.07 | Q34: =E34-P34 -> 17408.93 | X34: =E34 -> 18000 | Y34: =X34/1.12 -> 16071.429 | Z34: =Y34*0.12 -> 1928.5714 | AB34: 18000 | AC34: 16071.429 | AD34: 1928.5714 | AF34: =AC34-Y34 -> 0
A35: 1234 | B35: 45663 | C35: INV-10161 | D35: Aguilar IT Solutions | E35: 14072.56 | F35: Use of Address, Jan 24, 2025 to December 31, 2025 | G35: Maya Card | H35: UBP | J35: Virtual Office | K35: =E35 -> 14072.56 | L35: 0 | M35: =K35-L35 -> 14072.56 | N35: =E35-M35 -> 0 | P35: 462.1 | Q35: =E35-P35 -> 13610.46 | X35: =E35 -> 14072.56 | Y35: =X35/1.12 -> 12564.786 | Z35: =Y35*0.12 -> 1507.7743 | AB35: 14072.56 | AC35: 12564.786 | AD35: 1507.7743 | AF35: =AC35-Y35 -> 0
A36: 1235 | B36: 45663 | C36: INV-10191 | D36: JP Aclan | E36: 4700 | F36: Astra 1, Jan 3, 2025, 9:30 am to 4:30 pm | G36: Bank Transfer | H36: UBP | I36: UB723905 | J36: Meeting Rooms | K36: =E36 -> 4700 | L36: 0 | M36: =K36-L36 -> 4700 | N36: =E36-M36 -> 0 | X36: =E36 -> 4700 | Y36: =X36/1.12 -> 4196.4286 | Z36: =Y36*0.12 -> 503.57143 | AB36: 4700 | AC36: 4196.4286 | AD36: 503.57143 | AF36: =AC36-Y36 -> 0
A37: 1236 | B37: 45663 | C37: INV-10192 | D37: Feast Bellevue PM | E37: 5000 | F37: Rocket room, Jan 18, 2025, 8:00 am to 5:00 pm | G37: Bank Transfer | H37: UBP | I37: UB422188 - for tranfer SVI to SI | J37: Meeting Rooms | K37: =E37 -> 5000 | L37: 0 | M37: =K37-L37 -> 5000 | N37: =E37-M37 -> 0 | X37: =E37 -> 5000 | Y37: =X37/1.12 -> 4464.2857 | Z37: =Y37*0.12 -> 535.71429 | AB37: 5000 | AC37: 4464.2857 | AD37: 535.71429 | AF37: =AC37-Y37 -> 0
A38: 1237 | B38: 45663 | C38: INV-10071 | D38: Maso Fit Out Finishing Services | E38: 700 | F38: Rocket room, Dec 12, 2024, 1:00 pm to 2:00 pm | G38: Bank Transfer | H38: UBP | I38: UB1137273 | J38: Meeting Rooms | K38: =E38 -> 700 | L38: 0 | M38: =K38-L38 -> 700 | N38: =E38-M38 -> 0 | X38: =E38 -> 700 | Y38: =X38/1.12 -> 625 | Z38: =Y38*0.12 -> 75 | AB38: 700 | AC38: 625 | AD38: 75 | AE38: 2024 sales | AF38: =AC38-Y38 -> 0
A39: 1238 | B39: 45663 | C39: INV-10195 | D39: Vincent Carbajal | E39: 2371 | F39: Call room (Office Suite 9) , 12:30 pm to 7:30 pm | G39: Maya Card | H39: UBP | J39: Meeting Rooms | K39: =E39 -> 2371 | L39: 0 | M39: =K39-L39 -> 2371 | N39: =E39-M39 -> 0 | P39: 77.86 | Q39: =E39-P39 -> 2293.14 | X39: =E39 -> 2371 | Y39: =X39/1.12 -> 2116.9643 | Z39: =Y39*0.12 -> 254.03571 | AB39: 2371 | AC39: 2116.9643 | AD39: 254.03571 | AF39: =AC39-Y39 -> 0
A40: 1239 | B40: 45663 | C40: INV-10196 | D40: WonderPark Orbis Amusement, Inc. | E40: 2600 | F40: Astra 2, 12:00 pm to 4:00 pm - Jan 6, 2025 | G40: Maya Card | H40: UBP | J40: Meeting Rooms | K40: =E40 -> 2600 | L40: 0 | M40: =K40-L40 -> 2600 | N40: =E40-M40 -> 0 | P40: 85.38 | Q40: =E40-P40 -> 2514.62 | R40: =SUM(Q30:Q40) -> 36359.09 | X40: =E40 -> 2600 | Y40: =X40/1.12 -> 2321.4286 | Z40: =Y40*0.12 -> 278.57143 | AB40: 2600 | AC40: 2321.4286 | AD40: 278.57143 | AF40: =AC40-Y40 -> 0
...

Sheet AR
A1: SI | B1: Date | C1: Invoice | D1: Client Name | E1: AR Amount | F1: Description | G1: Mode of Payment | H1: Cash / Check Deposit | I1: Remarks | K1: GROSS | L1: CWT | M1: TOTAL | N1: Checking | P1: CC Fee | Q1: Net Amount
A3: 384 | B3: 45295 | D3: Team Bluefish Incorporated | E3: 3000 | F3: VO (Jan 3 - Feb 2, 2024) | G3: Check | H3: UBP | I3: CBC 0000039761
A4: 385 | B4: 45295 | D4: Karla Kris Properties Corporation | E4: 3000 | F4: VO (Jan 4 - Feb 3, 2024) | G4: Check | H4: UBP | I4: BDO 0000998782
A5: 386 | B5: 45301 | D5: FiveTwenty I.T Services | E5: 2866.08 | F5: Use of Address (Nov 1, 2023 - Jan 31, 2024) | G5: Check | H5: UBP | I5: UBP 0006438819
A6: 387 | B6: 45301 | D6: FiveTwenty I.T Services | E6: 2866.08 | F6: Use of Address (Feb 1 - Apr 30, 2024) | G6: Check | H6: UBP | I6: UBP 0006438820
A7: 388 | B7: 45303 | C7: INV-8288 | D7: Rendco Water Infrastructure Inc | E7: 251750 | F7: Security Deposit and Advance Subscription for Apollo 3 and Apollo 4/5 | G7: Check | H7: UBP | I7: BPI 1000131292
A8: 389 | B8: 45303 | D8: Rendco Water Infrastructure Inc | E8: 181723.21 | F8: Apollo 3 and 4/5 January 2024 Rental | G8: Check | H8: UBP
A9: 390 | B9: 45303 | D9: Irvine Analytics Solutions Inc | E9: 3000 | F9: VO (Jan 9 - Feb 8, 2024) | G9: Check | H9: UBP | I9: EWB 0000106104
A10: 391 | B10: 45303 | D10: Juan Enrique Flojo | E10: 1950 | F10: 50% DP for Rocket Room. Jan 14, 2024, 3p-8p | G10: Bank Transfer | H10: UBP | I10: UB490446
A11: 392 | B11: 45303 | D11: Mayfair We Care Philippines Inc | E11: 15000 | F11: Use of Address (Jan 8, 2024 - Jan 7, 2025) | G11: Check | H11: UBP | I11: MBTC 6434444696
A12: 393 | B12: 45307 | D12: Atty. Leo Malapitan Yatco | E12: 3000 | F12: VO (Jan 15 - Feb 14, 2024) | G12: Check | H12: UBP | I12: SB 0000154883
A13: 394 | B13: 45308 | C13: INV-8378 | D13: Therabilities South Inc | E13: =61250+65537.5 -> 126787.5 | F13: Security Deposit and Advanced Subscription for Voyager 4 (Applicable to June 2024) | G13: Check | H13: UBP | I13: MBTC 4950997969
A14: 395 | B14: 45308 | D14: Therabilities South Inc | E14: 65537.5 | F14: Voyager 4 Rent, Jan 22 - Feb 21, 2024 | G14: Check | H14: UBP | I14: MBTC 4950997969
A15: 396 | B15: 45309 | D15: Vets Tour Travel Service | E15: 3000 | F15: VO (Jan 18 - Feb 17, 2024) | G15: Check | H15: UBP | I15: BDO 0000340112
A16: 397 | B16: 45309 | D16: Stellar Forwarding & Transport Inc. | E16: 12801.79 | F16: Fixed Desk for 2 seats (Jan 22 - Feb 21, 2024) | G16: Check | H16: UBP | I16: BPI 6000109811
A17: 398 | B17: 45315 | D17: Star8 Asia Corporation | E17: 11464.29 | F17: Use of Address (Jan 28, 2024 - Jan 27, 2025) | G17: Check | H17: UBP | I17: PNB 2000001958 | K17: 12000 | L17: =K17/1.12*0.05 -> 535.71429 | M17: =K17-L17 -> 11464.286 | N17: =M17-E17 -> -0.0042857143
A18: 399 | B18: 45315 | D18: Wonderpark Orbis Amusement Inc | E18: 11464.29 | F18: Use of Address (Jan 28, 2024 - Jan 27, 2025) | G18: Check | H18: UBP | I18: BDO 0001611485 | K18: 12000 | L18: =K18/1.12*0.05 -> 535.71429 | M18: =K18-L18 -> 11464.286 | N18: =M18-E18 -> -0.0042857143
A19: 400 | B19: 45317 | D19: Baoya Propery Solutions Inc. | E19: 39200 | F19: Apollo 1 Rent February 2024 | G19: Check | H19: UBP | I19: BPI 1000293284
A20: 401 | B20: 45321 | D20: Onspec Global Research Solution Corp | E20: 12000 | F20: Use of Address (Feb 2, 2024 - Feb 1, 2025) | G20: Check | H20: UBP | I20: BDO 0000605992
A21: 402 | B21: 45321 | D21: Hygienic Process and Packaging Phil Inc | E21: 1250 | F21: Use of Address (Jan 17 - Feb 16, 2024) | G21: Check | H21: UBP | I21: SB 0000903642
A22: 403 | B22: 45321 | D22: Ad Tapia Petroleum Products Trading | E22: 2500 | F22: VO (Jan 25 - Feb 24, 2024) | G22: Check | H22: UBP | I22: BDO 00006554731
A23: 404 | B23: 45323 | D23: Onergy Safety Training Center | E23: 14250 | F23: Use of Address (Feb 9, 2024 - Feb 8, 2025) | G23: Bank Transfer | H23: UBP | I23: UB694781
A24: 405 | B24: 45323 | D24: Neufoods Venditio, (NFV) Corp | E24: 2500 | F24: VO (Feb 1 - Feb 29, 2024) | G24: Check | H24: UBP | I24: BPI 6000055587
A25: 406 | B25: 45323 | D25: Mahana Travel and Tours | E25: 2675 | F25: VO and Locker Rental (Feb 1-29, 2024) | G25: Check | H25: UBP | I25: BPI 6000126302 | K25: 2800 | L25: =K25/1.12*0.05 -> 125 | M25: =K25-L25 -> 2675 | N25: =M25-E25 -> 0
A26: 407 | B26: 45324 | D26: Garida Foods Inc | E26: 3000 | F26: VO (Feb 1 - Feb 29, 2024) | G26: Check | H26: UBP | I26: CB 0000062677
A27: 408 | B27: 45324 | D27: RLTY Property Corp | E27: 1000 | F27: Use of Address (Feb 1-29, 2024) | G27: Check | H27: UBP | I27: CBC 0000017022
A28: 409 | B28: 45324 | D28: JFAQ Enterprise | E28: 3000 | F28: VO (Feb 1 - Feb 29, 2024) | G28: Check | H28: UBP | I28: EWB 0008372224
A29: 410 | B29: 45324 | D29: qResults Group Philippines Incorporated | E29: 2866.07 | F29: VO (Feb 1 - Feb 29, 2024) | G29: Check | H29: UBP | I29: SB 0000830845 | K29: 3000 | L29: =K29/1.12*0.05 -> 133.92857 | M29: =K29-L29 -> 2866.0714 | N29: =M29-E29 -> 0.0014285714
A30: 411 | B30: 45324 | D30: Arian Publishing Corporation | E30: 955.36 | F30: Use of Address (Jan 28 - Feb 27, 2024) | G30: Check | H30: UBP | I30: BDO 0000452796 | K30: 1000 | L30: =K30/1.12*0.05 -> 44.642857 | M30: =K30-L30 -> 955.35714 | N30: =M30-E30 -> -0.0028571429
A31: 412 | B31: 45328 | D31: Karla Kris Properties Corporation | E31: 3000 | F31: VO (Feb 4 - Mar 3, 2024) | G31: Check | H31: UBP | I31: BDO 0000998783
A32: 413 | B32: 45328 | D32: Birch Registries Inc | E32: 1000 | F32: Use of Address (Feb 2 - Mar 1, 2024) | G32: Check | H32: UBP | I32: BPI 1000162413
A33: 414 | B33: 45328 | D33: Team Bluefish Incorporated | E33: 3000 | F33: VO (Feb 2 - Mar 1, 2024) | G33: Check | H33: UBP | I33: CBC 0000039762
A34: 415 | B34: 45329 | D34: Pastor Jojo Baldo | E34: 1150 | F34: 50% DP for Rocket Room, 2p-6p | G34: Maya QR Ph | H34: UBP | P34: =E34*0.015 -> 17.25 | Q34: =E34-P34 -> 1132.75
A35: 416 | B35: 45329 | D35: Kyoma Plant Tech Corporation | E35: 84262.5 | F35: Voyager 3 Rent March 2024 | G35: Check | H35: UBP | I35: BDO 0000433678 | K35: 88200 | L35: =K35/1.12*0.05 -> 3937.5 | M35: =K35-L35 -> 84262.5 | N35: =M35-E35 -> 0
A36: 417 | B36: 45331 | D36: Cindy Fernandez | E36: 1200 | F36: 50% DP for Rocket Room, Feb 15, 2024, 1p-5p | G36: Bank Transfer | H36: UBP | I36: UB232769
A37: 418 | B37: 45331 | D37: Environmentors Training Consultancy Services | E37: 36000 | F37: VO (Feb 15, 2024 - Feb 14, 2025) | G37: Cash | H37: UBP
A38: 419 | B38: 45348 | D38: Baoya Propery Solutions Inc. | E38: 39200 | F38: Apollo 1 Rental, March 2024 | G38: Check | H38: UBP | I38: BPI 1000118268
A39: 420 | B39: 45336 | D39: Jonathan Ortiz | E39: 400 | F39: DP for Apollo 2 (Call Room) Feb 24, 2024, 1p-3p | G39: Cash | H39: MBTC
A40: 421 | B40: 45338 | D40: Irvine Analytics Solutions Inc | E40: 3000 | F40: VO (Feb 9 - Mar 8, 2024) | G40: Check | H40: UBP | I40: EWB 0000106105
A41: 422 | B41: 45338 | D41: Atty Leo Malapitan Yatco | E41: 3000 | F41: VO (Feb 9 - Mar 8, 2024) | G41: Check | H41: UBP | I41: SB 0000154927
...

Sheet Xero Sales
A1: Xero Sales Q1 2025
A2: Shirefolk, Inc. (Doing business under the name and style of Launchpad Coworking)
A3: For the period 1 January 2025 to 31 March 2025
A5: Source contains Receivable Prepayment, Receivable Payment, Receive Money, Receivable Invoice
A7: Date | B7: Source | C7: Contact | D7: Description | E7: Reference | F7: Debit | G7: Credit | H7: Gross | I7: Running Balance | J7: Tax | K7: Tax Rate | L7: Account
A9: Tax Exempt
A10: 45658 | B10: Receive Money | C10: Philippine Nutri-Foods Corporation | D10: Philippine Nutri-Foods Corporation - Solicitation from Clients for Christmas Party | F10: 0 | G10: 1000 | H10: 1000 | I10: =(G10 - F10) -> 1000 | J10: 0 | K10: 0 | L10: Other Revenue from Clients
A11: 45692 | B11: Receive Money | C11: Environmentors Training Consultancy Services | D11: Environmentors Training Consultancy Services - Excess payment | F11: 0 | G11: 0.52 | H11: 0.52 | I11: =((I10 + G11) - F11) -> 1000.52 | J11: 0 | K11: 0 | L11: Other Revenue from Clients
A12: 45670 | B12: Receivable Invoice | C12: Digibeacon BPO Inc. | D12: Digibeacon BPO Inc. - Office Suite 9 (Call Room), ₱1,400.00, 1:00 pm to 5:00 pm , Jan 13, 2025 | E12: INV-10227 | F12: 0 | G12: 1440 | H12: 1440 | I12: =((I11 + G12) - F12) -> 2440.52 | J12: 0 | K12: 0 | L12: Meeting Room
A13: 45667 | B13: Receivable Invoice | C13: Anxa Limited | D13: Anxa Limited - LPC - Virtual Office, ₱3,125.00, Jan 1, 2025 - Dec 31, 2025 | E13: INV-10251 | F13: 0 | G13: 37500 | H13: 37500 | I13: =((I12 + G13) - F13) -> 39940.52 | J13: 0 | K13: 0 | L13: Monthly Membership: Virtual Office with 10 Day Pass
A14: 45710 | B14: Receivable Invoice | C14: Bebang Enterprise, Inc. | D14: Bebang Enterprise, Inc. - Coworking Space, ₱1,500.00/ 10:00 am to 11:00 am - Feb 23, 2025 | E14: INV-10549 | F14: 0 | G14: 1500 | H14: 1500 | I14: =((I13 + G14) - F14) -> 41440.52 | J14: 0 | K14: 0 | L14: Meeting Room
A15: Total Tax Exempt | F15: =SUM(F10:F14) -> 0 | G15: =SUM(G10:G14) -> 41440.52 | H15: =SUM(H10:H14) -> 41440.52 | I15: =I14 -> 41440.52 | J15: =SUM(J10:J14) -> 0
A17: VAT on Sales (Services)
A18: 45658 | B18: Receivable Invoice | C18: Blue Point Properties, Inc. | D18: Blue Point Properties, Inc. - LPC - Virtual Office Renewal, ₱1,375.00, Jan 29, 2025 - Feb 27, 2025 | E18: INV-10408 | F18: 0 | G18: 1227.68 | H18: 1375 | I18: =((I17 + G18) - F18) -> 1227.68 | J18: 147.32 | K18: 12 | L18: Monthly Membership: Business Address Registration
A19: 45658 | B19: Receivable Invoice | C19: Joenafe Tinapan | D19: Joenafe Tinapan - LPC - Locker Rental, ₱300.00, Jan 1, 2025 - Jan 31, 2025 | E19: INV-10522 | F19: 0 | G19: 267.86 | H19: 300 | I19: =((I18 + G19) - F19) -> 1495.54 | J19: 32.14 | K19: 12 | L19: Add Ons: Locker Rental
A20: 45658 | B20: Receivable Invoice | C20: Lotti Consulting Inc. | D20: Lotti Consulting Inc. - LPC - Virtual Office, ₱3,500.00, Jan 1, 2025 - Dec 31, 2025 | E20: INV-10105 | F20: 0 | G20: 37500 | H20: 42000 | I20: =((I19 + G20) - F20) -> 38995.54 | J20: 4500 | K20: 12 | L20: Monthly Membership: Virtual Office with 10 Day Pass
A21: 45658 | B21: Receivable Invoice | C21: Marketing Master IO OPC | D21: MARKETING MASTER IO OPC - LPC - Virtual Office, ₱3,500.00, Jan 1, 2025 - Dec 31, 2025 | E21: INV-10154 | F21: 0 | G21: 37500 | H21: 42000 | I21: =((I20 + G21) - F21) -> 76495.54 | J21: 4500 | K21: 12 | L21: Monthly Membership: Virtual Office with 10 Day Pass
A22: 45658 | B22: Receivable Invoice | C22: MASO Fit Out Finishing Services | D22: MASO Fit Out Finishing Services - LPC - Virtual Office, ₱3,000.00, Dec 2, 2024 - Dec 1, 2025 | E22: INV-10070 | F22: 0 | G22: 32142.86 | H22: 36000 | I22: =((I21 + G22) - F22) -> 108638.4 | J22: 3857.14 | K22: 12 | L22: Monthly Membership: Virtual Office with 10 Day Pass
A23: 45658 | B23: Receivable Invoice | C23: MASO Fit Out Finishing Services | D23: MASO Fit Out Finishing Services - LPC - Virtual Office, ₱3,000.00, Dec 2, 2025 - Dec 31, 2025 (Pro-rated ) | E23: INV-10070 | F23: 0 | G23: 2592.05 | H23: 2903.1 | I23: =((I22 + G23) - F23) -> 111230.45 | J23: 311.05 | K23: 12 | L23: Monthly Membership: Virtual Office with 10 Day Pass
A24: 45658 | B24: Receivable Invoice | C24: MASO Fit Out Finishing Services | D24: MASO Fit Out Finishing Services - LPC - Locker Rental, ₱300.00, Dec 2, 2024 - Dec 1, 2025 | E24: INV-10070 | F24: 0 | G24: 3214.29 | H24: 3600 | I24: =((I23 + G24) - F24) -> 114444.74 | J24: 385.71 | K24: 12 | L24: Add Ons: Locker Rental
A25: 45658 | B25: Receivable Invoice | C25: MASO Fit Out Finishing Services | D25: MASO Fit Out Finishing Services - LPC - Locker Rental, ₱300.00, Dec 2, 2025 - Dec 31, 2025 (Pro-rated) | E25: INV-10070 | F25: 0 | G25: 259.82 | H25: 291 | I25: =((I24 + G25) - F25) -> 114704.56 | J25: 31.18 | K25: 12 | L25: Add Ons: Locker Rental
A26: 45658 | B26: Receivable Invoice | C26: Megaluck Prime Solutions Inc. | D26: Megaluck Prime Solutions Inc. - LPC - Virtual Office Renewal, ₱1,250.00, Jan 1, 2025 - Dec 31, 2025 | E26: INV-10162 | F26: 0 | G26: 13392.86 | H26: 15000 | I26: =((I25 + G26) - F26) -> 128097.42 | J26: 1607.14 | K26: 12 | L26: Monthly Membership: Business Address Registration
A27: 45658 | B27: Receivable Invoice | C27: Metals Focus Data Ltd. | D27: Metals Focus Data Ltd. - LP Suites Office 1, ₱33,600.00, Jan 1, 2025 - Jan 31, 2025 | E27: INV-10128 | F27: 0 | G27: 30000 | H27: 33600 | I27: =((I26 + G27) - F27) -> 158097.42 | J27: 3600 | K27: 12 | L27: Monthly Membership: Private Office
A28: 45658 | B28: Receivable Invoice | C28: NeuFoods Venditio, (NFV) Corp. | D28: NeuFoods Venditio, (NFV) Corp. - LPC - Virtual Office Renewal, ₱1,250.00, Jan 1, 2025 - Dec 31, 2025 | E28: INV-10032 | F28: 0 | G28: 13392.86 | H28: 15000 | I28: =((I27 + G28) - F28) -> 171490.28 | J28: 1607.14 | K28: 12 | L28: Monthly Membership: Business Address Registration
A29: 45658 | B29: Receivable Invoice | C29: Offsite Solutions Inc | D29: Offsite Solutions Inc - LPC - Virtual Office, Use of Address, ₱1,375.00, Jan 1, 2025 - Dec 31, 2025 | E29: INV-10490 | F29: 0 | G29: 14732.14 | H29: 16500 | I29: =((I28 + G29) - F29) -> 186222.42 | J29: 1767.86 | K29: 12 | L29: Monthly Membership: Business Address Registration
... A218: 45679 | B218: Receivable Invoice | C218: Fujitsu Engineering Technologies Philippines, Inc. | D218: Fujitsu Engineering Technologies Philippines, Inc. - Astra 1, ₱5,700.00 / 8:30 am to 5:30 pm - Jan 28, 2025 | E218: INV-10292 | F218: 0 | G218: 4580.36 | H218: 5130 | I218: =((I217 + G218) - F218) -> 1798324 | J218: 549.64 | K218: 12 | L218: Meeting Room
A219: 45679 | B219: Receive Money | C219: Global Ventures Inc. | D219: Global Ventures Inc. - Initial Deposit for UA Jan 2025 | F219: 0 | G219: 1116.07 | H219: 1250 | I219: =(G219 - F219) -> 1116.07 | J219: 133.93 | K219: 12 | L219: Monthly Membership: Business Address Registration
A220: 45679 | B220: Receivable Invoice | C220: Global Ventures Inc. | D220: Global Ventures Inc. - LPC - Virtual Office Renewal, ₱1,250.00, Jan 20, 2025 - Feb 19, 2025 | E220: INV-10319 | F220: 0 | G220: 1116.07 | H220: 1250 | I220: =((I219 + G220) - F220) -> 2232.14 | J220: 133.93 | K220: 12 | L220: Monthly Membership: Business Address Registration
A221: 45679 | B221: Receivable Invoice | C221: Grace Quizon | D221: Grace Quizon - LPC - Printing B&W | E221: INV-10296 | F221: 0 | G221: 758.93 | H221: 850 | I221: =((I220 + G221) - F221) -> 2991.07 | J221: 91.07 | K221: 12 | L221: Add Ons: Printing
A222: 45679 | B222: Receivable Invoice | C222: JLZ Import Export Corporation | D222: JLZ Import Export Corporation - LPC - Fixed Desk - Fixed Desk-01, ₱6,700.00, Jan 20, 2025 - Feb 19, 2025 | E222: INV-10302 | F222: 0 | G222: 5982.14 | H222: 6700 | I222: =((I221 + G222) - F222) -> 8973.21 | J222: 717.86 | K222: 12 | L222: Monthly Membership: Permanent Desk
A223: 45679 | B223: Receivable Invoice | C223: JP Aclan | D223: JP Aclan - Office Suite 10, ₱3,300.00, 10:30 am to 3:30 pm- Jan 21, 2025 | E223: INV-10304 | F223: 0 | G223: 2946.43 | H223: 3300 | I223: =((I222 + G223) - F223) -> 11919.64 | J223: 353.57 | K223: 12 | L223: Meeting Room
A224: 45679 | B224: Receivable Invoice | C224: Karina Tosca Feria | D224: Karina Tosca Feria - LPC - Whole Day Fly Pass | E224: INV-10299 | F224: 0 | G224: 491.07 | H224: 550 | I224: =((I223 + G224) - F224) -> 12410.71 | J224: 58.93 | K224: 12 | L224: Walk Ins: Whole Day Pass
A225: 45679 | B225: Receivable Invoice | C225: Lion Lamb Graphic Design Services | D225: Lion Lamb Graphic Design Services - LPC - Virtual Office Renewal, ₱1,250.00, Jan 17, 2025 - Feb 16, 2025 | E225: INV-10303 | F225: 0 | G225: 1116.07 | H225: 1250 | I225: =((I224 + G225) - F225) -> 13526.78 | J225: 133.93 | K225: 12 | L225: Monthly Membership: Business Address Registration
A226: 45679 | B226: Receivable Invoice | C226: Michelle Anne Cruz | D226: Michelle Anne Cruz - LPC - 3 Hour Fly Pass | E226: INV-10295 | F226: 0 | G226: 267.86 | H226: 300 | I226: =((I225 + G226) - F226) -> 13794.64 | J226: 32.14 | K226: 12 | L226: Walk Ins: 3 Hour Fly Pass
A227: 45679 | B227: Receivable Invoice | C227: mPAD Systems, Inc. | D227: mPAD Systems, Inc. - LPC - Virtual Office, ₱3,000.00, Jan 19, 2025 - Feb 18, 2025 | E227: INV-10351 | F227: 0 | G227: 2678.57 | H227: 3000 | I227: =((I226 + G227) - F227) -> 16473.21 | J227: 321.43 | K227: 12 | L227: Monthly Membership: Virtual Office with 10 Day Pass
A228: 45679 | B228: Receivable Invoice | C228: Noel Bernal | D228: Noel Bernal - LPC - 3 Hour Fly Pass | E228: INV-10298 | F228: 0 | G228: 267.86 | H228: 300 | I228: =((I227 + G228) - F228) -> 16741.07 | J228: 32.14 | K228: 12 | L228: Walk Ins: 3 Hour Fly Pass
A229: 45679 | B229: Receivable Invoice | C229: SynerPark Ventures Inc. | D229: SynerPark Ventures Inc. - Astra 2, ₱1,400.00, 10:00 am to 12:00 pm- Jan 22, 2025 | E229: INV-10294 | F229: 0 | G229: 1250 | H229: 1400 | I229: =((I228 + G229) - F229) -> 17991.07 | J229: 150 | K229: 12 | L229: Meeting Room
A230: 45679 | B230: Receivable Invoice | C230: Uphouse Business Professionals Consultancy Corporation | D230: Uphouse Business Professionals Consultancy Corporation - LPC - Virtual Office, ₱3,500.00, Jan 22, 2025 - Dec 21, 2025 | E230: INV-10345 | F230: 0 | G230: 34375 | H230: 38500 | I230: =((I229 + G230) - F230) -> 52366.07 | J230: 4125 | K230: 12 | L230: Monthly Membership: Virtual Office with 10 Day Pass
A231: 45679 | B231: Receivable Invoice | C231: Uphouse Business Professionals Consultancy Corporation | D231: Uphouse Business Professionals Consultancy Corporation - LPC - Virtual Office, ₱112.90, Dec 22, 2025 - Dec 31, 2025 | E231: INV-10345 | F231: 0 | G231: 1008.04 | H231: 1129 | I231: =((I230 + G231) - F231) -> 53374.11 | J231: 120.96 | K231: 12 | L231: Monthly Membership: Business Address Registration
... A292: 45688 | B292: Receivable Invoice | C292: WonderPark Orbis Amusement, Inc. | D292: WonderPark Orbis Amusement, Inc. - LPC - Virtual Office Renewal, ₱40.32, Dec 28, 2025 - Dec 31, 2025 (Prorated) | E292: INV-10360 | F292: 0 | G292: 144 | H292: 161.28 | I292: =((I291 + G292) - F292) -> 442351.14 | J292: 17.28 | K292: 12 | L292: Monthly Membership: Business Address Registration
...

Sheet Xero Purchases G
A1: Xero Purchases Goods 2025
A2: Shirefolk, Inc. (Doing business under the name and style of Launchpad Coworking)
A3: For the period 1 January 2025 to 31 March 2025
A5: Source contains Payable Invoice, Payable Payment, Spend Money
A6: Tax Rate Name contains VAT on Purchases (Goods), VAT on Purchases (Capital Goods), VAT on Purchases (Goods Not Qual for Input Tax)
A8: Date | B8: Source | C8: Contact | D8: Description | E8: Reference | F8: Credit | G8: Gross | H8: Net | I8: Running Balance | J8: Tax | K8: Tax Rate | L8: Account
A10: VAT on Purchases (Goods Not Qual for Input Tax)
A11: 45663 | B11: Spend Money | C11: Aquaholix Water Refilling Station | D11: Aquaholix Water Refilling Station - Purified water | E11: PCF-2888 | F11: 0 | G11: 270 | H11: 270 | I11: 0 | J11: 0 | K11: 0 | L11: Office and Pantry Supplies
A12: 45665 | B12: Spend Money | C12: Edwin C. Nopuente - Prop | D12: Edwin C. Napuente - Prop - 5 Bottles Purified Water | E12: PCF 2893 | F12: 0 | G12: 150 | H12: 150 | I12: 0 | J12: 0 | K12: 0 | L12: Office and Pantry Supplies
A13: 45666 | B13: Spend Money | C13: Patricio L Boncayao Jr Law Office | D13: Patricio L Boncayao Jr Law Office - Notorial Fee for BIR Affidavit | E13: PCF 2895 | F13: 0 | G13: 150 | H13: 150 | I13: 0 | J13: 0 | K13: 0 | L13: Miscellaneous Expense
A14: 45673 | B14: Spend Money | C14: BIR | D14: BIR - Documentary stamp for Sworn Declaration ( 6-Xchange) | E14: PCF 2906 | F14: 0 | G14: 60 | H14: 60 | I14: 0 | J14: 0 | K14: 0 | L14: Miscellaneous Expense
A16: 45695 | B16: Spend Money | C16: Edwin C. Nopuente - Prop | D16: Edwin C. Napuente - Prop - 3 Bottles of Purified water | E16: PCF - 2936 | F16: 0 | G16: 90 | H16: 90 | I16: 0 | J16: 0 | K16: 0 | L16: Office and Pantry Supplies - Others
A17: 45707 | B17: Spend Money | C17: Edwin C. Nopuente - Prop | D17: Edwin C. Napuente - Prop - 7 Bottles of Purified Water | E17: PCF 2955 | F17: 0 | G17: 210 | H17: 210 | I17: 0 | J17: 0 | K17: 0 | L17: Office and Pantry Supplies
A18: 45716 | B18: Payable Invoice | C18: GBrothers Foods, Inc. | D18: GBrothers Foods, Inc. - Marketing Expense for July 2024 Ref: SI 0005447 | E18: UBP-0724-829 (4) | F18: 0 | G18: 136.07 | H18: 136.07 | I18: 0 | J18: 0 | K18: 0 | L18: Marketing Expense
A20: 45728 | B20: Spend Money | C20: Grand Union Supermarket, Inc. | D20: Grand Union Supermarket, Inc. - Pantry Supplies - Tax Exempt | E20: PCF-2984 | F20: 0 | G20: 588 | H20: 588 | I20: 0 | J20: 0 | K20: 0 | L20: Office and Pantry Supplies
A21: 45728 | B21: Spend Money | C21: Edwin C. Nopuente - Prop | D21: Edwin C. Napuente - Prop - Water (4 bottles) | E21: PCF-2985 | F21: 0 | G21: 120 | H21: 120 | I21: 0 | J21: 0 | K21: 0 | L21: Office and Pantry Supplies
A22: 45729 | B22: Spend Money | C22: Edwin C. Nopuente - Prop | D22: Edwin C. Napuente - Prop - Water - 3 bottles | E22: PCF-2986 | F22: 0 | G22: 90 | H22: 90 | I22: 0 | J22: 0 | K22: 0 | L22: Office and Pantry Supplies
A23: 45730 | B23: Spend Money | C23: Edwin C. Nopuente - Prop | D23: Edwin C. Napuente - Prop - Water - 4 bottles | E23: PCF-2987 | F23: 0 | G23: 120 | H23: 120 | I23: 0 | J23: 0 | K23: 0 | L23: Office and Pantry Supplies
A24: 45733 | B24: Spend Money | C24: Edwin C. Nopuente - Prop | D24: Edwin C. Napuente - Prop - Water- 5 bottles | E24: PCF-2988 | F24: 0 | G24: 150 | H24: 150 | I24: 0 | J24: 0 | K24: 0 | L24: Office and Pantry Supplies
... A36: 45747 | B36: Payable Invoice | C36: Grand Union Supermarket, Inc. | D36: Grand Union Supermarket, Inc. - Marketing Expense for Aug 2024 Ref: SI41000247 | E36: UBP-0824-855 (3) | F36: 0 | G36: 170.3 | H36: 170.3 | I36: 0 | J36: 0 | K36: 0 | L36: Marketing Expense
A37: Total VAT on Purchases (Goods Not Qual for Input Tax) | F37: 0 | G37: 4244.37 | H37: 4244.37 | I37: 0 | J37: 0
A39: VAT on Purchases (Goods)
A40: 45664 | B40: Spend Money | C40: Grand Union Supermarket, Inc. | D40: Grand Union Supermarket, Inc. - Pantry Supplies | E40: PCF-2889 | F40: 0 | G40: 835.05 | H40: 745.58 | I40: 0 | J40: 89.47 | K40: 0.12 | L40: Office and Pantry Supplies
A41: 45665 | B41: Payable Invoice | C41: HEBREWSKAPE TRADING INC. | D41: HEBREWSKAPE TRADING INC. - Coffee Beans (Hazel Nut 12 kg.) | E41: UBP-0125-934 | F41: 0 | G41: 7929.6 | H41: 7080 | I41: 0 | J41: 849.6 | K41: 0.12 | L41: Office and Pantry Supplies
A42: 45665 | B42: Spend Money | C42: Alabang Supermarket Corp | D42: Alabang Supermarket Corp - Pantry Supplies | E42: PCF 2892 | F42: 0 | G42: 150 | H42: 133.93 | I42: 0 | J42: 16.07 | K42: 0.12 | L42: Office and Pantry Supplies
A43: 45666 | B43: Spend Money | C43: Grand Union Supermarket, Inc. | D43: Grand Union Supermarket, Inc. - Office and Pantry Supplies | E43: PCF 2894 | F43: 0 | G43: 2225.5 | H43: 1987.05 | I43: 0 | J43: 238.45 | K43: 0.12 | L43: Office and Pantry Supplies
A44: 45667 | B44: Spend Money | C44: Edwin C. Nopuente - Prop | D44: Edwin C. Napuente - Prop - 8 bottles Purifiied water | E44: PCF 2897 | F44: 0 | G44: 240 | H44: 214.29 | I44: 0 | J44: 25.71 | K44: 0.12 | L44: Office and Pantry Supplies - Others
A45: 45670 | B45: Spend Money | C45: Edwin C. Nopuente - Prop | D45: Edwin C. Napuente - Prop - 5 bottles purified water | E45: PCF 2899 | F45: 0 | G45: 150 | H45: 133.93 | I45: 0 | J45: 16.07 | K45: 0.12 | L45: Office and Pantry Supplies - Others
A46: 45670 | B46: Spend Money | C46: Grand Union Supermarket, Inc. | D46: Grand Union Supermarket, Inc. - Pantry Supplies | E46: PCF 2898 | F46: 0 | G46: 3591.3 | H46: 3206.52 | I46: 0 | J46: 384.78 | K46: 0.12 | L46: Office and Pantry Supplies
A47: 45671 | B47: Spend Money | C47: Edwin C. Nopuente - Prop | D47: Edwin C. Napuente - Prop - 3 Bottles of purified water | E47: PCF 2900 | F47: 0 | G47: 90 | H47: 80.36 | I47: 0 | J47: 9.64 | K47: 0.12 | L47: Office and Pantry Supplies - Others
A48: 45672 | B48: Spend Money | C48: Edwin C. Nopuente - Prop | D48: Edwin C. Napuente - Prop - 5 bottles of Purified water | E48: PCF 2903 | F48: 0 | G48: 150 | H48: 133.93 | I48: 0 | J48: 16.07 | K48: 0.12 | L48: Office and Pantry Supplies - Others
A49: 45674 | B49: Spend Money | C49: Edwin C. Nopuente - Prop | D49: Edwin C. Napuente - Prop - 2 Bottles Purified Water | E49: PCF-2910 | F49: 0 | G49: 60 | H49: 53.57 | I49: 0 | J49: 6.43 | K49: 0.12 | L49: Office and Pantry Supplies - Others
A50: 45675 | B50: Spend Money | C50: Wilcon Depot, Inc. | D50: Wilcon Depot, Inc. - Light Bulb for Reception Area | E50: PCF 2902 | F50: 0 | G50: 521.55 | H50: 465.67 | I50: 0 | J50: 55.88 | K50: 0.12 | L50: Office and Pantry Supplies - Others
A51: 45675 | B51: Spend Money | C51: shopee | D51: shopee - LP3 Government permit Holder for Display | E51: PCF-2908 | F51: 0 | G51: 299 | H51: 266.96 | I51: 0 | J51: 32.04 | K51: 0.12 | L51: Office and Pantry Supplies - Others
... A116: 45747 | B116: Payable Invoice | C116: New Quepe Hardware Co., Inc. | D116: New Quepe Hardware Co., Inc. - Progress Billing No. 4 Materials Ref: Sales Invoice 425270 | E116: UBP-0424-837(148) | F116: 0 | G116: 23430 | H116: 20919.64 | I116: 0 | J116: 2510.36 | K116: 0.12 | L116: Leasehold Improvements
A117: Total VAT on Purchases (Goods) | F117: 0 | G117: 252687.87 | H117: 225614.23 | I117: 0 | J117: 27073.64
A119: Total | F119: 0 | G119: 256932.24 | H119: 229858.6 | I119: 0 | J119: 27073.64
A123: Xero Goods Q2 2025
A124: Shirefolk, Inc. (Doing business under the name and style of Launchpad Coworking)
A125: For the period April 1, 2025 to June 30, 2025
...

Sheet Schedule of CG Input Tax
A1: CAPITAL GOODS (AGGREGATE AMOUNT EXCEEDS 1M)
A2: INPUT TAX
A4: LEASEHOLD IMPROVEMENTS
A5: DATE PURCHASED | B5: Amount (Net of VAT) | C5: Input Tax | D5: Estimated Life | E5: Monthly Allowable Input Tax | F5: 45292 | G5: 45323 | H5: 45352 | I5: 45383 | J5: 45413 | K5: 45444 | L5: 45474 | M5: 45505 | N5: 45536 | O5: 45566 | P5: 45597 | Q5: 45627 | R5: 45658 | S5: 45689 | T5: 45717 | U5: 45748 | V5: 45778 | W5: 45809 | X5: 45839 | Y5: 45870 | Z5: 45901 | AA5: RUNNING BALANCE
A6: 45323 | B6: 1029347.7 | C6: =B6*12% -> 123521.72 | D6: 60 | E6: =C6/D6 -> 2058.6954 | F6: 0 | G6: =$E$6 -> 2058.6954 | H6: =$E$6 -> 2058.6954 | I6: =$E$6 -> 2058.6954 | J6: =$E$6 -> 2058.6954 | K6: =$E$6 -> 2058.6954 | L6: =$E$6 -> 2058.6954 | M6: =$E$6 -> 2058.6954 | N6: =$E$6 -> 2058.6954 | ... Z6: =$E$6 -> 2058.6954 | AA6: =C6-SUM(G6:W6) -> 88523.901 | AB6: =AA6+T6+S6+R6 -> 94699.987
A7: 45412 | B7: 1600801.7 | C7: =B7*12% -> 192096.21 | D7: 60 | E7: =C7/D7 -> 3201.6034 | I7: =$E$7 -> 3201.6034 | J7: =$E$7 -> 3201.6034 | K7: =$E$7 -> 3201.6034 | L7: =$E$7 -> 3201.6034 | M7: =$E$7 -> 3201.6034 | N7: =$E$7 -> 3201.6034 | O7: =$E$7 -> 3201.6034 | P7: =$E$7 -> 3201.6034 | ... Z7: =$E$7 -> 3201.6034 | AA7: =C7-SUM(G7:W7) -> 144072.15 | AB7: =AA7+T7+S7+R7 -> 153676.97
A10: AIRCON AND LEASED LINE SERVER
A11: DATE PURCHASED | B11: Amount (Net of VAT) | C11: Input Tax | D11: Estimated Life | E11: Monthly Allowable Input Tax | F11: 45292 | G11: 45323 | H11: 45352 | I11: 45383 | J11: 45413 | K11: 45444 | L11: 45474 | M11: 45505 | N11: 45536 | O11: 45566 | P11: 45597 | Q11: 45627 | R11: =R5 -> 45658 | S11: =S5 -> 45689 | T11: =T5 -> 45717 | U11: =U5 -> 45748 | V11: =V5 -> 45778 | W11: =W5 -> 45809 | X11: =X5 -> 45839 | Y11: =Y5 -> 45870 | Z11: =Z5 -> 45901 | AA11: RUNNING BALANCE
A12: 45301 | B12: 1191785.7 | C12: =B12*12% -> 143014.29 | D12: 60 | E12: =C12/D12 -> 2383.5714 | F12: =$E$12 -> 2383.5714 | G12: =$E$12 -> 2383.5714 | H12: =$E$12 -> 2383.5714 | I12: =$E$12 -> 2383.5714 | J12: =$E$12 -> 2383.5714 | K12: =$E$12 -> 2383.5714 | L12: =$E$12 -> 2383.5714 | M12: =$E$12 -> 2383.5714 | ... Z12: =$E$12 -> 2383.5714 | AA12: =C12-SUM(F12:W12) -> 100110 | AB12: =AA12+T12+S12+R12 -> 107260.71
F14: 45292 | G14: 45323 | H14: 45352 | I14: 45383 | J14: 45413 | K14: 45444 | L14: 45474 | M14: 45505 | N14: 45536 | O14: 45566 | P14: 45597 | Q14: 45627 | R14: =R11 -> 45658 | S14: =S11 -> 45689 | T14: =T11 -> 45717 | U14: =U11 -> 45748 | V14: =V11 -> 45778 | W14: =W11 -> 45809 | X14: =X11 -> 45839 | Y14: =Y11 -> 45870 | Z14: =Z11 -> 45901 | AA14: RUNNING BALANCE
A15: TOTAL | F15: =F6+F12+F7 -> 2383.5714 | G15: =G6+G12+G7 -> 4442.2668 | H15: =H6+H12+H7 -> 4442.2668 | I15: =I6+I12+I7 -> 7643.8703 | J15: =J6+J12+J7 -> 7643.8703 | K15: =K6+K12+K7 -> 7643.8703 | L15: =L6+L12+L7 -> 7643.8703 | M15: =M6+M12+M7 -> 7643.8703 | N15: =N6+N12+N7 -> 7643.8703 | O15: =SUM(O6:O7,O12) -> 7643.8703 | P15: =SUM(P6:P7,P12) -> 7643.8703 | Q15: =SUM(Q6:Q7,Q12) -> 7643.8703 | R15: =SUM(R6:R7,R12) -> 7643.8703 | S15: =SUM(S6:S7,S12) -> 7643.8703 | T15: =SUM(T6:T7,T12) -> 7643.8703 | U15: =SUM(U6:U7,U12) -> 7643.8703 | V15: =SUM(V6:V7,V12) -> 7643.8703 | ... Z15: =SUM(Z6:Z7,Z12) -> 7643.8703 | AA15: =AA6+AA12+AA7 -> 332706.06 | AB15: =AA15+T15+S15+R15 -> 355637.67

Sheet Xero Purchases S
A1: Xero Purchases Services 2025
A2: Shirefolk, Inc. (Doing business under the name and style of Launchpad Coworking)
A3: For the period 1 January 2025 to 31 March 2025
A5: Source contains Payable Payment, Payable Prepayment, Spend Money
A6: Tax Rate Name contains VAT on Purchases (Services by Non-residents), VAT on Purchases (Services Not Qual for Input Tax), VAT on Purchases (Services), VAT on Purchases
A8: Date | B8: Source | C8: Contact | D8: Description | E8: Reference | F8: Credit | G8: Gross | H8: Net | I8: Running Balance | J8: Tax | K8: Tax Rate | L8: Account
A10: VAT on Purchases
A11: 45693 | B11: Spend Money | C11: Philippine Allied Enterprises Corporation | D11: Philippine Allied Enterprises Corporation - Parking fee of Sir Bon Excess of the tree 3hrs Parking | E11: PCF - 2932 | F11: 0 | G11: 15 | H11: 13.39 | I11: 0 | J11: 1.61 | K11: 0.12 | L11: Toll and Parking - Others
A12: Total VAT on Purchases | F12: 0 | G12: 15 | H12: 13.39 | I12: 0 | J12: 1.61
A14: VAT on Purchases (Services Not Qual for Input Tax)
A15: 45671 | B15: Spend Money | C15: Patricio L Boncayao Jr Law Office | D15: Patricio L Boncayao Jr Law Office - Notarial fee of Sworn declaration | E15: PCF 2901 | F15: 0 | G15: 150 | H15: 150 | I15: 0 | J15: 0 | K15: 0 | L15: Miscellaneous Expense
A16: 45673 | B16: Spend Money | C16: Patricio L Boncayao Jr Law Office | D16: Patricio L Boncayao Jr Law Office - Notorial fee of private office lease contract (CJ Philipines Inc.) | E16: PCF 2905 | F16: 0 | G16: 230 | H16: 230 | I16: 0 | J16: 0 | K16: 0 | L16: Miscellaneous Expense
A17: 45681 | B17: Spend Money | C17: Lizardo Carlos& Lizardo III | D17: Lizardo Carlos& Lizardo III - Notorial Fee of Gross Sales (shirefolk inc) | E17: PCF-2917 | F17: 0 | G17: 200 | H17: 200 | I17: 0 | J17: 0 | K17: 0 | L17: Miscellaneous Expense
A19: 45708 | B19: Payable Payment | C19: Jesaly A. Dacara - Prop. | D19: Payment: Jesaly A. Dacara - Prop. | E19: UB499278 | F19: 0 | G19: 2400 | H19: 2400 | I19: 0 | J19: 0 | K19: 0 | L19: Other General and Administrative Expenses
A20: 45716 | B20: Payable Payment | C20: Randy Benedict F. Ferrer- Prop. | D20: Payment: Randy Benedict F. Ferrer- Prop. | E20: UB499333 | F20: 0 | G20: 8000 | H20: 8000 | I20: 0 | J20: 0 | K20: 0 | L20: Other Employee Benefits
A22: 45724 | B22: Payable Payment | C22: Ohana Domestic Services | D22: Payment: Ohana Domestic Services | E22: UB534099 | F22: 0 | G22: 6000 | H22: 6000 | I22: 0 | J22: 0 | K22: 0 | L22: Repairs and Maintenance
A23: 45724 | B23: Payable Payment | C23: Ohana Domestic Services | D23: Payment: Ohana Domestic Services | E23: UB534099 | F23: 0 | G23: 4800 | H23: 4800 | I23: 0 | J23: 0 | K23: 0 | L23: Repairs and Maintenance
A24: 45724 | B24: Payable Payment | C24: Ohana Domestic Services | D24: Payment: Ohana Domestic Services | E24: UB534099 | F24: 0 | G24: 6000 | H24: 6000 | I24: 0 | J24: 0 | K24: 0 | L24: Repairs and Maintenance
A25: 45724 | B25: Payable Payment | C25: Ohana Domestic Services | D25: Payment: Ohana Domestic Services | E25: UB534099 | F25: 0 | G25: 1500 | H25: 1500 | I25: 0 | J25: 0 | K25: 0 | L25: Repairs and Maintenance
A26: Total VAT on Purchases (Services Not Qual for Input Tax) | F26: 0 | G26: 29280 | H26: 29280 | I26: 0 | J26: 0
A28: VAT on Purchases (Services)
A29: 45664 | B29: Spend Money | C29: Golden Arches Development Corporation - Commerce Avenue | D29: Golden Arches Development Corporation - Commerce Avenue - Lundi for Accounting Endorsement | E29: PCF 2891 | F29: 0 | G29: 380.58 | H29: 339.8 | I29: 0 | J29: 40.78 | K29: 0.12 | L29: Meals Expense - Others
A30: 45666 | B30: Payable Payment | C30: PLDT Inc. | D30: Payment: PLDT Inc. | E30: UB 2002548176 | F30: 0 | G30: 54432 | H30: 48600 | I30: 0 | J30: 5832 | K30: 0.12 | L30: Communication Expense
A31: 45666 | B31: Spend Money | C31: Lalamove Philippines | D31: Lalamove Philippines - Coffee Beans Delivery Fee (50/50) Shared with SVI | E31: PCF 2896 | F31: 0 | G31: 75 | H31: 66.96 | I31: 0 | J31: 8.04 | K31: 0.12 | L31: Shipping and Delivery Expense
A32: 45666 | B32: Payable Payment | C32: Pestman Specialists Inc | D32: Payment: Pestman Specialists Inc | E32: UB 2002548170 | F32: 0 | G32: 2000 | H32: 1785.71 | I32: 0 | J32: 214.29 | K32: 0.12 | L32: Repairs and Maintenance
A33: 45666 | B33: Payable Payment | C33: Pestman Specialists Inc | D33: Payment: Pestman Specialists Inc | E33: UB 2002548170 | F33: 0 | G33: 1500 | H33: 1339.29 | I33: 0 | J33: 160.71 | K33: 0.12 | L33: Repairs and Maintenance
A34: 45666 | B34: Payable Payment | C34: Pestman Specialists Inc | D34: Payment: Pestman Specialists Inc | E34: UB 2002548170 | F34: 0 | G34: 1000 | H34: 892.86 | I34: 0 | J34: 107.14 | K34: 0.12 | L34: Repairs and Maintenance
A35: 45669 | B35: Payable Payment | C35: PLDT Inc. | D35: Payment: PLDT Inc. | E35: S82906083 | F35: 0 | G35: 1546.01 | H35: 1380.37 | I35: 0 | J35: 165.64 | K35: 0.12 | L35: Communication Expense
A36: 45669 | B36: Payable Payment | C36: PLDT Inc. | D36: Payment: PLDT Inc. | E36: S82906083 | F36: 0 | G36: 74501.99 | H36: 66519.63 | I36: 0 | J36: 7982.36 | K36: 0.12 | L36: Communication Expense
A37: 45669 | B37: Payable Payment | C37: PLDT Inc. | D37: Payment: PLDT Inc. | E37: S82909092 | F37: 0 | G37: 32.09 | H37: 28.65 | I37: 0 | J37: 3.44 | K37: 0.12 | L37: Communication Expense
A38: 45669 | B38: Payable Payment | C38: PLDT Inc. | D38: Payment: PLDT Inc. | E38: S82909092 | F38: 0 | G38: 1546.01 | H38: 1380.37 | I38: 0 | J38: 165.64 | K38: 0.12 | L38: Communication Expense
A39: 45678 | B39: Payable Payment | C39: Philippine Allied Enterprises Corporation | D39: Payment: Philippine Allied Enterprises Corporation | E39: UB 2002548173 | F39: 0 | G39: 23829.12 | H39: 21276 | I39: 0 | J39: 2553.12 | K39: 0.12 | L39: Common Area Charges
