Workbook

Sheet Summary of CG Purchased 
A1: PURCHASES OF CAPITAL GOODS
A5: APRIL 2019 | C5: MONTHS | D5: AMOUNT NET OF VAT | E5: INPUT TAX | F5: ALLOWABLE DEDUCTIONS | G5: BALANCE OF INPUT TAX | H5: TO BE CARRIED UNTIL | I5: PER MONTH | K5: (Per Month x 3Months)
B6: FURNITURE & FIXTURES | C6: =3*12 -> 36 | D6: 2934806.6 | E6: =D6*0.12 -> 352176.8 | F6: =E6/C6 -> 9782.6888 | G6: =E6-F6 -> 342394.11 | H6: MARCH 2022 | I6: =F6 -> 9782.6888 | K6: =I6*3 -> 29348.066
B7: LEASEHOLD IMPROVEMENT | C7: =5*12 -> 60 | D7: 5737496.5 | E7: =D7*0.12 -> 688499.58 | F7: =E7/C7 -> 11474.993 | G7: =E7-F7 -> 677024.58 | H7: MARCH 2024 | I7: =F7 -> 11474.993 | K7: =I7*3 -> 34424.979
B8: OFFICE EQUIPMENT | C8: =3*12 -> 36 | D8: 301766.26 | E8: =D8*0.12 -> 36211.951 | F8: =E8 -> 36211.951 | G8: =E8-F8 -> 0
B10: TOTAL | D10: 8974069.4 | E10: =SUM(E6:E8) -> 1076888.3 | F10: =SUM(F6:F8) -> 57469.633 | G10: =SUM(G6:G8) -> 1019418.7 | I10: =SUM(I6:I8) -> 21257.682 | K10: =I10*3 -> 63773.045
A13: MAY 2019 | C13: MONTHS | D13: AMOUNT NET OF VAT | E13: INPUT TAX | F13: ALLOWABLE DEDUCTIONS | G13: BALANCE OF INPUT TAX | H13: TO BE CARRIED UNTIL | I13: PER MONTH
B14: FURNITURE & FIXTURES | C14: =3*12 -> 36 | D14: 0 | E14: =D14*0.12 -> 0 | F14: =E14/C14 -> 0 | G14: =E14-F14 -> 0 | I14: =F14 -> 0
B15: LEASEHOLD IMPROVEMENT | C15: =5*12 -> 60 | D15: 597634.03 | E15: =D15*0.12 -> 71716.084 | F15: =E15 -> 71716.084 | G15: =E15-F15 -> 0 | M15: =L16/36 -> 81522.406 | N15: =M16*0.12 -> 264132.6 | O15: =N15/27 -> 9782.6888
B16: OFFICE EQUIPMENT | C16: =3*12 -> 36 | E16: =D16*0.12 -> 0 | F16: =E16 -> 0 | G16: =E16-F16 -> 0 | L16: =D6 -> 2934806.6 | M16: 2201105 | N16: =L16-M16 -> 733701.66 | O16: =N16/M15 -> 9
L17: 5737496.5 | M17: 4876872 | N17: =L17-M17 -> 860624.47 | O17: =(L17/60)*9 -> 860624.47 | P17: =N17-O17 -> -0.0019999994
B18: TOTAL | D18: 597634.03 | E18: =SUM(E14:E16) -> 71716.084 | F18: =SUM(F14:F16) -> 71716.084 | G18: =SUM(G14:G16) -> 0 | L18: =SUM(L16:L17) -> 8672303.1 | M18: =SUM(M16:M17) -> 7077977 | N18: =SUM(N16:N17) -> 1594326.1
A21: JUNE 2019 | C21: MONTHS | D21: AMOUNT NET OF VAT | E21: INPUT TAX | F21: ALLOWABLE DEDUCTIONS | G21: BALANCE OF INPUT TAX | H21: TO BE CARRIED UNTIL | I21: PER MONTH
B22: FURNITURE & FIXTURES | C22: =3*12 -> 36 | D22: 105000 | E22: =D22*0.12 -> 12600 | F22: =E22 -> 12600 | G22: =E22-F22 -> 0 | I22: 0
B23: LEASEHOLD IMPROVEMENT | C23: =5*12 -> 60 | D23: 159618.7 | E23: =D23*0.12 -> 19154.244 | F23: =E23 -> 19154.244 | G23: =E23-F23 -> 0
B24: OFFICE EQUIPMENT | C24: =3*12 -> 36 | D24: 1071.43 | E24: =D24*0.12 -> 128.5716 | F24: =E24 -> 128.5716 | G24: =E24-F24 -> 0
B26: TOTAL | D26: 265690.13 | E26: =SUM(E22:E24) -> 31882.816 | F26: =SUM(F22:F24) -> 31882.816 | G26: =SUM(G22:G24) -> 0
A29: JULY 2019 | C29: MONTHS | D29: AMOUNT NET OF VAT | E29: INPUT TAX | F29: ALLOWABLE DEDUCTIONS | G29: BALANCE OF INPUT TAX | H29: TO BE CARRIED UNTIL | I29: PER MONTH
B30: FURNITURE & FIXTURES | C30: =3*12 -> 36 | D30: 0 | E30: =D30*0.12 -> 0 | F30: =E30 -> 0 | G30: =E30-F30 -> 0 | I30: 0
B31: LEASEHOLD IMPROVEMENT | C31: =5*12 -> 60 | D31: 174808.8 | E31: =D31*0.12 -> 20977.056 | F31: =E31 -> 20977.056 | G31: =E31-F31 -> 0
B32: OFFICE EQUIPMENT | C32: =3*12 -> 36 | D32: 0 | E32: =D32*0.12 -> 0 | F32: =E32 -> 0 | G32: =E32-F32 -> 0
B34: TOTAL | D34: 174808.8 | E34: =SUM(E30:E32) -> 20977.056 | F34: =SUM(F30:F32) -> 20977.056 | G34: =SUM(G30:G32) -> 0
A37: AUG 2019 | C37: MONTHS | D37: AMOUNT NET OF VAT | E37: INPUT TAX | F37: ALLOWABLE DEDUCTIONS | G37: BALANCE OF INPUT TAX | H37: TO BE CARRIED UNTIL | I37: PER MONTH
B38: FURNITURE & FIXTURES | C38: =3*12 -> 36 | D38: 0 | E38: =D38*0.12 -> 0 | F38: =E38 -> 0 | G38: =E38-F38 -> 0 | I38: 0
B39: LEASEHOLD IMPROVEMENT | C39: =5*12 -> 60 | D39: 0 | E39: =D39*0.12 -> 0 | F39: =E39 -> 0 | G39: =E39-F39 -> 0
B40: OFFICE EQUIPMENT | C40: =3*12 -> 36 | D40: 0 | E40: =D40*0.12 -> 0 | F40: =E40 -> 0 | G40: =E40-F40 -> 0
B42: TOTAL | D42: 0 | E42: =SUM(E38:E40) -> 0 | F42: =SUM(F38:F40) -> 0 | G42: =SUM(G38:G40) -> 0
A45: SEPT 2019 | C45: MONTHS | D45: AMOUNT NET OF VAT | E45: INPUT TAX | F45: ALLOWABLE DEDUCTIONS | G45: BALANCE OF INPUT TAX | H45: TO BE CARRIED UNTIL | I45: PER MONTH
B46: FURNITURE & FIXTURES | C46: =3*12 -> 36 | D46: 135625 | E46: =D46*0.12 -> 16275 | F46: =E46 -> 16275 | G46: =E46-F46 -> 0 | I46: 0
B47: LEASEHOLD IMPROVEMENT | C47: =5*12 -> 60 | D47: 93973.57 | E47: =D47*0.12 -> 11276.828 | F47: =E47 -> 11276.828 | G47: =E47-F47 -> 0
B48: OFFICE EQUIPMENT | C48: =3*12 -> 36 | D48: 0 | E48: =D48*0.12 -> 0 | F48: =E48 -> 0 | G48: =E48-F48 -> 0
B50: TOTAL | D50: 229598.57 | E50: =SUM(E46:E48) -> 27551.828 | F50: =SUM(F46:F48) -> 27551.828 | G50: =SUM(G46:G48) -> 0
A53: OCT 2019 | C53: MONTHS | D53: AMOUNT NET OF VAT | E53: INPUT TAX | F53: ALLOWABLE DEDUCTIONS | G53: BALANCE OF INPUT TAX | H53: TO BE CARRIED UNTIL | I53: PER MONTH
B54: FURNITURE & FIXTURES | C54: =3*12 -> 36 | D54: 0 | E54: =D54*0.12 -> 0 | F54: =E54 -> 0 | G54: =E54-F54 -> 0 | I54: 0
B55: LEASEHOLD IMPROVEMENT | C55: =5*12 -> 60 | D55: 0 | E55: =D55*0.12 -> 0 | F55: =E55 -> 0 | G55: =E55-F55 -> 0
B56: OFFICE EQUIPMENT | C56: =3*12 -> 36 | D56: 0 | E56: =D56*0.12 -> 0 | F56: =E56 -> 0 | G56: =E56-F56 -> 0
B58: TOTAL | D58: 0 | E58: =SUM(E54:E56) -> 0 | F58: =SUM(F54:F56) -> 0 | G58: =SUM(G54:G56) -> 0
A61: NOV 2019 | C61: MONTHS | D61: AMOUNT NET OF VAT | E61: INPUT TAX | F61: ALLOWABLE DEDUCTIONS | G61: BALANCE OF INPUT TAX | H61: TO BE CARRIED UNTIL | I61: PER MONTH
B62: FURNITURE & FIXTURES | C62: =3*12 -> 36 | D62: 0 | E62: =D62*0.12 -> 0 | F62: =E62 -> 0 | G62: =E62-F62 -> 0 | I62: 0
B63: LEASEHOLD IMPROVEMENT | C63: =5*12 -> 60 | D63: 4973.57 | E63: =D63*0.12 -> 596.8284 | F63: =E63 -> 596.8284 | G63: =E63-F63 -> 0
...

Sheet VAT Schedule
A2: Shirefolk Ventures Inc.
A3: YEAR 2025
B4: Zero-Rated Sales | C4: Vatable-Sales | D4: Vat on Sales (Output Tax) | E4: Input Tax Carried Over | F4: VAT on Purchases (Goods Not Qual for Input Tax) | G4: VAT on Purchases (Services Not Qualified for Input Tax) | H4: Purchases Capital Goods | I4: Purchases of Goods (Other than Capital Goods) | J4: Purchases of Services | K4: Vat on Purchases of Capital Goods (Input Tax) | L4: Allowable Vat on Purchases of Capital Goods (Input Tax) | M4: Vat on Purchases of Goods other than Capital Goods & Services (Input Tax) | N4: Total Vat on Purchases (Input Tax) | O4: VAT Payable | P4: in eBIR Form | Q4: difference | R4: Def | S4: Amount Filed | T4: Date Filed | U4: Date Paid | V4: SLSP
A6: Beg. Bal. | O6: -3893209.4
A7: January | B7: =SI!S33+SI!S54 -> 3584965.3 | C7: =SUM(SI!T2:T56) -> 469932.75 | D7: =C7*0.12 -> 56391.93 | E7: =O6 -> -3893209.4 | F7: - | G7: 31021.02 | H7: 0 | I7: 25893.44 | J7: 1177215.4 | K7: =H7*0.12 -> 0 | L7: ='Schedule of CG Input Tax'!BZ144 -> 2867.5801 | M7: =SUM(I7:J7)*0.12 -> 144373.06 | N7: =SUM(K7:M7) -> 147240.64 | O7: =$D7+$E7-$N7 -> -3984058.1
A8: February | B8: =SI!S86 -> 1792482.7 | C8: =SUM(SI!T58:T94) -> 283831.88 | D8: =C8*0.12 -> 34059.826 | E8: =O7 -> -3984058.1 | F8: 504 | G8: 10390 | H8: 0 | I8: 50742.38 | J8: 1199276.3 | K8: =H8*0.12 -> 0 | L8: ='Schedule of CG Input Tax'!CA144 -> 2867.5801 | M8: =SUM(I8:J8)*0.12 -> 150002.24 | N8: =SUM(K8:M8) -> 152869.82 | O8: =$D8+$E8-$N8 -> -4102868.1
A9: March | B9: 0 | C9: =SUM(SI!T96:T132) -> 153426.48 | D9: =C9*0.12 -> 18411.178 | E9: =O8 -> -4102868.1 | F9: 3270 | G9: 21317 | H9: 0 | I9: 34955.36 | J9: 1219543.8 | K9: =H9*0.12 -> 0 | L9: ='Schedule of CG Input Tax'!CB144 -> 2867.5801 | M9: =SUM(I9:J9)*0.12 -> 150539.9 | N9: =SUM(K9:M9) -> 153407.48 | O9: =$D9+$E9-$N9 -> -4237864.4
A10: 1st Quarter | B10: =SUM(B7:B9) -> 5377448 | C10: =SUM(C7:C9) -> 907191.12 | D10: =C10*0.12 -> 108862.93 | E10: =O6 -> -3893209.4 | F10: =SUM(F7:F9) -> 3774 | G10: =SUM(G7:G9) -> 62728.02 | H10: =SUM(H7:H9) -> 0 | I10: =SUM(I7:I9) -> 111591.18 | J10: =SUM(J7:J9) -> 3596035.5 | K10: =SUM(K7:K9) -> 0 | L10: =SUM(L7:L9) -> 8602.7403 | M10: =SUM(M7:M9) -> 444915.2 | N10: =SUM(N7:N9) -> 453517.94 | O10: =$D10+$E10-$N10-0.01 -> -4237864.4 | P10: -4225435.8 | Q10: =O10-P10 -> -12428.576
K11: =K10-'Xero Purchases G 2025'!I143 -> 0
A12: Amended
A13: Beg. Bal. | O13: -3893209.4
A14: January | B14: =sum('Q1 Amendment'!H282:H295) -> 1594105.1 | C14: =sum('Q1 Amendment'!G25:G30,'Q1 Amendment'!G32:G37,'Q1 Amendment'!G39:G100,'Q1 Amendment'!G261:G264) -> 535735 | D14: =C14*0.12 -> 64288.201 | E14: =O13 -> -3893209.4 | F14: 0 | G14: =SUM('Xero Purchases S 2025'!I20:I21) -> 450 | H14: =SUM('Xero Purchases G 2025'!E148:E149) -> 0 | I14: =SUM('Xero Purchases G 2025'!F34:F49) -> 25893.44 | J14: =SUM('Xero Purchases S 2025'!I35:I49) -> 1202218.4 | K14: =H14*0.12 -> 0 | L14: ='Schedule of CG Input Tax'!BZ144 -> 2867.5801 | M14: =SUM(I14:J14)*0.12 -> 147373.42 | N14: =SUM(K14:M14) -> 150241 | O14: =$D14+$E14-$N14 -> -3979162.2
A15: February | B15: =sum('Q1 Amendment'!H296:H309) -> 1594105.1 | C15: =sum('Q1 Amendment'!G101:G102,'Q1 Amendment'!G104:G178) -> 549685.9 | D15: =C15*0.12 -> 65962.308 | E15: =O14 -> -3979162.2 | F15: =SUM('Xero Purchases G 2025'!F10:F12) -> 504 | G15: =sum('Xero Purchases S 2025'!I23:I26) -> 10390 | H15: 0 | I15: =sum('Xero Purchases G 2025'!F51:F73) -> 50742.38 | J15: =sum('Xero Purchases S 2025'!I51:I65) -> 1197826.5 | K15: =H15*0.12 -> 0 | L15: ='Schedule of CG Input Tax'!CA144 -> 2867.5801 | M15: =SUM(I15:J15)*0.12 -> 149828.27 | N15: =SUM(K15:M15) -> 152695.85 | O15: =$D15+$E15-$N15 -> -4065895.7
A16: March | B16: =sum('Q1 Amendment'!H310:H323) -> 1594105.1 | C16: =sum('Q1 Amendment'!G179:G248) -> 360326.05 | D16: =C16*0.12 -> 43239.126 | E16: =O15 -> -4065895.7 | F16: =SUM('Xero Purchases G 2025'!F14:F30) -> 3270 | G16: =SUM('Xero Purchases S 2025'!I28:I31) -> 2817 | H16: 0 | I16: =sum('Xero Purchases G 2025'!F75:F89) -> 34955.36 | J16: =SUM('Xero Purchases S 2025'!I67:I82) -> 1224259.3 | K16: =H16*0.12 -> 0 | L16: ='Schedule of CG Input Tax'!CB144 -> 2867.5801 | M16: =SUM(I16:J16)*0.12 -> 151105.76 | N16: =SUM(K16:M16) -> 153973.34 | O16: =$D16+$E16-$N16 -> -4176629.9
A17: 1st Quarter Amended | B17: =SUM(B14:B16) -> 4782315.4 | C17: =SUM(C14:C16) -> 1445747 | D17: =C17*0.12 -> 173489.63 | E17: =O13 -> -3893209.4 | F17: =SUM(F14:F16) -> 3774 | G17: =SUM(G14:G16) -> 13657 | H17: =SUM(H14:H16) -> 0 | I17: =SUM(I14:I16) -> 111591.18 | J17: =SUM(J14:J16) -> 3624304.2 | K17: =SUM(K14:K16) -> 0 | L17: =SUM(L14:L16) -> 8602.7403 | M17: =SUM(M14:M16) -> 448307.45 | N17: =SUM(N14:N16) -> 456910.19 | O17: =$D17+$E17-$N17 -> -4176629.9 | Q17: =O17-P17 -> -4176629.9
B18: =B17-'Q1 Amendment'!G327 -> 9.3132257e-10 | C18: =C17-'Q1 Amendment'!G268 -> 0.0042857144 | F18: =F17-'Xero Purchases G 2025'!F31 -> 0 | H18: =H17-'Xero Purchases G 2025'!E150 -> 0 | I18: =I17-'Xero Purchases G 2025'!F90 -> 0 | J18: =J17-'Xero Purchases S 2025'!I83 -> 0 | K18: =K17-'Xero Purchases G 2025'!I150 -> 0
A20: April | E20: =O10 -> -4237864.4 | N20: =SUM(K20:M20) -> 0 | O20: =$D20+$E20-$N20 -> -4237864.4
A21: May | E21: =O20 -> -4237864.4 | N21: =SUM(K21:M21) -> 0 | O21: =$D21+$E21-$N21 -> -4237864.4
A22: June | E22: =O21 -> -4237864.4 | N22: =SUM(K22:M22) -> 0 | O22: =$D22+$E22-$N22 -> -4237864.4
A23: 2nd Quarter | B23: =SUM(B20:B22) -> 0 | C23: =SUM(C20:C22) -> 0 | D23: =C23*0.12 -> 0 | E23: =E20 -> -4237864.4 | N23: =SUM(K23:M23) -> 0 | O23: =D23+E23-N23 -> -4237864.4 | Q23: =O23-P23 -> -4237864.4
A25: July | E25: =O23 -> -4237864.4 | N25: =SUM(K25:M25) -> 0 | O25: =$D25+$E25-$N25 -> -4237864.4
A26: August | E26: =O25 -> -4237864.4 | N26: =SUM(K26:M26) -> 0 | O26: =$D26+$E26-$N26 -> -4237864.4
A27: September | E27: =O26 -> -4237864.4 | N27: =SUM(K27:M27) -> 0 | O27: =$D27+$E27-$N27 -> -4237864.4
A28: 3rd Quarter | B28: =SUM(B25:B27) -> 0 | C28: =SUM(C25:C27) -> 0 | D28: =C28*0.12 -> 0 | E28: =E25 -> -4237864.4 | F28: =SUM(F25:F27) -> 0 | G28: =SUM(G25:G27) -> 0 | H28: =SUM(H25:H27) -> 0 | I28: =SUM(I25:I27) -> 0 | J28: =SUM(J25:J27) -> 0 | K28: =SUM(K25:K27) -> 0 | M28: =SUM(M25:M27) -> 0 | N28: =SUM(L28:M28) -> 0 | O28: =D28+E28-N28 -> -4237864.4 | Q28: =O28-P28 -> -4237864.4
A30: Oct | C30: 0 | D30: =C30*12% -> 0 | E30: =O28 -> -4237864.4 | K30: =H30*0.12 -> 0 | M30: =(SUM(I30:J30)*0.12) -> 0 | N30: =SUM(K30:M30) -> 0 | O30: =$D30+$E30-$N30 -> -4237864.4
A31: Nov | C31: 0 | D31: =C31*12% -> 0 | E31: =O30 -> -4237864.4 | K31: =H31*0.12 -> 0 | M31: =(SUM(I31:J31)*0.12) -> 0 | N31: =SUM(K31:M31) -> 0 | O31: =$D31+$E31-$N31 -> -4237864.4
A32: Dec | C32: 0 | D32: =C32*12% -> 0 | E32: =O31 -> -4237864.4 | K32: =H32*0.12 -> 0 | M32: =(SUM(I32:J32)*0.12) -> 0 | N32: =SUM(K32:M32) -> 0 | O32: =$D32+$E32-$N32-0.01 -> -4237864.4
A33: 4th Quarter | B33: =SUM(B30:B32) -> 0 | C33: =SUM(C30:C32) -> 0 | D33: =C33*0.12 -> 0 | E33: =O28 -> -4237864.4 | F33: =SUM(F30:F32) -> 0 | G33: =SUM(G30:G32) -> 0 | H33: =SUM(H30:H32) -> 0 | I33: =SUM(I30:I32) -> 0 | J33: =SUM(J30:J32) -> 0 | K33: =SUM(K30:K32) -> 0 | L33: =SUM(L30:L32) -> 0 | M33: =SUM(M30:M32) -> 0 | N33: =SUM(N30:N32) -> 0 | O33: =D33+E33-N33 -> -4237864.4
C34: =C33 -> 0 | F34: =F33 -> 0 | H34: =H33 -> 0 | I34: =I33 -> 0 | J34: =J33 -> 0 | K34: =K33 -> 0
A35: Year Total | B35: =B10+B23+B28+B33 -> 5377448 | C35: =C10+C23+C28+C33 -> 907191.12 | D35: =D10+D23+D28+D33 -> 108862.93 | E35: =E10+E23+E28+E33 -> -16606803 | F35: =F10+F23+F28+F33 -> 3774 | G35: =G10+G23+G28+G33 -> 62728.02 | H35: =H10+H23+H28+H33 -> 0 | I35: =I10+I23+I28+I33 -> 111591.18 | ... N35: =N10+N23+N28+N33 -> 453517.94 | O35: =O33 -> -4237864.4

Sheet SI
A1: SI | B1: Date | C1: Invoice Number | D1: Client Name | E1: OR Amount | F1: Description | G1: Mode of Payment | H1: Cash / Check Deposit | I1: Remarks | J1: Type of Service | K1: GROSS | L1: CWT | M1: TOTAL | O1: CC Fee/Charge | P1: Net Amount | Q1: Checking | S1: GROSS AMOUNT | T1: NET AMOUNT | U1: VAT AMOUNT
A2: 0353 | B2: 45660 | C2: INV-2426 | D2: Timedly Solutions, Inc. | E2: 3500 | F2: Virtual Office, Jan 1, 2025 - Jan 31, 2025 | G2: Check | H2: UBP | I2: Security Bank 0000509610 | J2: Virtual Office | K2: 3500 | S2: =E2 -> 3500 | T2: =S2/1.12 -> 3125 | U2: =T2*12% -> 375 | V2: =T2+U2-S2 -> 0
A3: 0354 | B3: 45663 | C3: INV-2435 | D3: Intertool Precision Group Inc | E3: 2100 | F3: Meeting Room 3, 3:00 pm to 6:00 pm | G3: Maya QR Standee | H3: UBP | J3: Meeting Rooms | K3: 2100 | O3: 9.38 | P3: =E3-O3 -> 2090.62 | S3: =E3 -> 2100 | T3: =S3/1.12 -> 1875 | U3: =T3*12% -> 225 | V3: =T3+U3-S3 -> 0
A4: 0355 | D4: CANCELLED | S4: =E4 | T4: =S4/1.12 -> 0 | U4: =T4*12% -> 0 | V4: =T4+U4-S4 -> 0
A5: 0356 | B5: 45664 | C5: INV-2437 | D5: Bluvision Surveillance and Analytics Inc. | E5: 4500 | F5: Meeting Room 1, Jan 8, 2025, 9:00 am to 1:00 pm | G5: Maya QR Standee | H5: UBP | J5: Meeting Rooms | K5: 4500 | O5: 20.09 | P5: =E5-O5 -> 4479.91 | S5: =E5 -> 4500 | T5: =S5/1.12 -> 4017.8571 | U5: =T5*12% -> 482.14286 | V5: =T5+U5-S5 -> 0
A6: 0357 | B6: 45665 | C6: INV-2467 | D6: Lawrence Alexander | E6: 20 | F6: Printing | G6: Maya QR Standee | H6: UBP | J6: Add-Ons | K6: 20 | O6: 0.09 | P6: =E6-O6 -> 19.91 | S6: =E6 -> 20 | T6: =S6/1.12 -> 17.857143 | U6: =T6*12% -> 2.1428571 | V6: =T6+U6-S6 -> 0
A7: 0358 | B7: 45665 | C7: INV-2438 | D7: Limuel Libres | E7: 350 | F7: Wholeday Flypass (Student) | G7: Cash | H7: MBTC | J7: Walk-Ins | K7: 350 | S7: =E7 -> 350 | T7: =S7/1.12 -> 312.5 | U7: =T7*12% -> 37.5 | V7: =T7+U7-S7 -> 0
A8: 0359 | B8: 45666 | C8: INV-2441 | D8: Margarita Bariring | E8: 5500 | F8: Monthly Flypass | G8: Maya Card | H8: UBP | J8: Monthly Membership | K8: 5500 | O8: 180.6 | P8: =E8-O8 -> 5319.4 | S8: =E8 -> 5500 | T8: =S8/1.12 -> 4910.7143 | U8: =T8*12% -> 589.28571 | V8: =T8+U8-S8 -> 0
A9: 0360 | B9: 45666 | C9: INV-2442 | D9: MARRO FASHION STYLING STUDIO | E9: 2400 | F9: Meeting Room 2, 9:30 am to 12:00 nn | G9: Maya Card | H9: UBP | J9: Meeting Rooms | K9: 2400 | O9: 78.81 | P9: =E9-O9 -> 2321.19 | S9: =E9 -> 2400 | T9: =S9/1.12 -> 2142.8571 | U9: =T9*12% -> 257.14286 | V9: =T9+U9-S9 -> 0
A10: 0361 | B10: 45666 | C10: INV-2443 | D10: F.A BAUTISTA & PARTNERS | E10: 5500 | F10: Meeting Room 3, January 10, 2025, 8:30 am to 5:00 pm | G10: Maya QR Standee | H10: UBP | J10: Meeting Rooms | K10: 5500 | O10: 24.55 | P10: =E10-O10 -> 5475.45 | Q10: =SUM(P8:P10) -> 13116.04 | S10: =E10 -> 5500 | T10: =S10/1.12 -> 4910.7143 | U10: =T10*12% -> 589.28571 | V10: =T10+U10-S10 -> 0
A11: 0362 | B11: 45666 | C11: INV-2436 | D11: Moom Health Services Corp | E11: 4000 | F11: Virtual Office, Jan 4, 2025 - Feb 3, 2025 | G11: Check | H11: UBP | I11: BDO 0000158359 | J11: Virtual Office | K11: 4000 | S11: =E11 -> 4000 | T11: =S11/1.12 -> 3571.4286 | U11: =T11*12% -> 428.57143 | V11: =T11+U11-S11 -> 0
A12: 0363 | B12: 45667 | C12: INV-2468 | D12: Lawrence Alexander | E12: 10 | F12: Printing | G12: Maya QR Standee | H12: UBP | J12: Add-Ons | K12: 10 | O12: 0.04 | P12: =E12-O12 -> 9.96 | S12: =E12 -> 10 | T12: =S12/1.12 -> 8.9285714 | U12: =T12*12% -> 1.0714286 | V12: =T12+U12-S12 -> 0
A13: 0364 | B13: 45667 | C13: INV-2445 | D13: Kevin Carmelina | E13: 1600 | F13: Meeting Room 2, 1:00 pm to 3:00 pm | G13: Maya Card | H13: UBP | J13: Meeting Rooms | K13: 1600 | O13: 52.54 | P13: =E13-O13 -> 1547.46 | S13: =E13 -> 1600 | T13: =S13/1.12 -> 1428.5714 | U13: =T13*12% -> 171.42857 | V13: =T13+U13-S13 -> 0
A14: 0365 | D14: CANCELLED | S14: =E14 | T14: =S14/1.12 -> 0 | U14: =T14*12% -> 0 | V14: =T14+U14-S14 -> 0
A15: 0366 | D15: CANCELLED | S15: =E15 | T15: =S15/1.12 -> 0 | U15: =T15*12% -> 0 | V15: =T15+U15-S15 -> 0
A16: 0367 | B16: 45667 | C16: INV-2446 | D16: Paolo De Asis | E16: 600 | F16: Wholeday Flypass | G16: Cash | H16: MBTC | K16: 600 | S16: =E16 -> 600 | T16: =S16/1.12 -> 535.71429 | U16: =T16*12% -> 64.285714 | V16: =T16+U16-S16 -> 0
A17: 0368 | B17: 45667 | C17: INV-2447 | D17: Brey Reyes | E17: 2400 | F17: Meeting Room 2, 4:30 pm to 6:00 pm | G17: Maya Card | H17: UBP | J17: Walk-Ins | K17: 2400 | O17: 78.81 | P17: =E17-O17 -> 2321.19 | Q17: =P13+P17+P19+AR!N127 -> 22073.19 | S17: =E17 -> 2400 | T17: =S17/1.12 -> 2142.8571 | U17: =T17*12% -> 257.14286 | V17: =T17+U17-S17 -> 0
A18: 0369 | B18: 45668 | C18: INV-2450 | D18: AIMS Industrial Supplies | E18: 84400 | F18: Meeting Room 1, 2 and 3, February 3-7, 2025 | G18: AR 435 (42200) Maya Card (42200) | H18: UBP | I18: UB1297258 | J18: Meeting Rooms | K18: 84400 | O18: 1385.72 | P18: =42200-O18 -> 40814.28 | Q18: =42200-O18 -> 40814.28 | S18: =E18 -> 84400 | T18: =S18/1.12 -> 75357.143 | U18: =T18*12% -> 9042.8571 | V18: =T18+U18-S18 -> 0
A19: 0370 | B19: 45670 | C19: INV-2448 | D19: E Gonzales Law Office | E19: 17322.63 | F19: Use of Address, Jan 15, 2025 to Dec 31, 2025 | G19: Maya Card (Jan 10) | H19: UBP | J19: Virtual Office | K19: 17322.63 | O19: 568.83 | P19: =E19-O19 -> 16753.8 | S19: =E19 -> 17322.63 | T19: =S19/1.12 -> 15466.634 | U19: =T19*12% -> 1855.9961 | V19: =T19+U19-S19 -> 0
A20: 0371 | B20: 45670 | C20: INV-2452 | D20: Arkiya Francine Orosco | E20: 2400 | F20: Meeting Room 2, Jan 13, 2025, 9:00 am to 12:00 pm | G20: Cash | H20: MBTC | J20: Meeting Rooms | K20: 2400 | S20: =E20 -> 2400 | T20: =S20/1.12 -> 2142.8571 | U20: =T20*12% -> 257.14286 | V20: =T20+U20-S20 -> 0
A21: 0372 | D21: CANCELLED | S21: =E21 | T21: =S21/1.12 -> 0 | U21: =T21*12% -> 0 | V21: =T21+U21-S21 -> 0
A22: 0373 | B22: 45670 | C22: INV-2451 | D22: Sightechs Corporation | E22: 24000 | F22: Virtual Office, Jan 1, 2025 - Jun 30, 2025 | G22: Bank Transfer | H22: UBP | I22: UB1060687 | J22: Virtual Office | K22: 24000 | S22: =E22 -> 24000 | T22: =S22/1.12 -> 21428.571 | U22: =T22*12% -> 2571.4286 | V22: =T22+U22-S22 -> 0
A23: 0374 | B23: 45671 | C23: INV-2432/INV-2433/INV-2428/INV-2429/INV-2430/INV-2431 | D23: iHub Solutions (Philippines) Inc. | E23: 127841.68 | F23: Meeting Room 2, 7am to 4pm, Jan (full) , Feb - Apr (DP) & Locker Rental (jan-Apr) & Virtual Office (Jan 20 - Dec 31, 2025) | G23: Bank Transfer | H23: UBP | I23: UB799581 | J23: Meeting Rooms | K23: 127841.68 | S23: =E23 -> 127841.68 | T23: =S23/1.12 -> 114144.36 | U23: =T23*12% -> 13697.323 | V23: =T23+U23-S23 -> 0
A24: 0375 | B24: 45671 | C24: INV-2427/INV-2425 | D24: Recruitgo Philippines Inc. | E24: =8500+34300 -> 42800 | F24: Meeting Room 1 rental, Jan 9, 16, 23, 30 & Locker Rental (Jan 2025) | G24: Bank Transfer | H24: UBP | I24: UB1200210 | J24: Meeting Rooms | K24: =8500+34300 -> 42800 | S24: =E24 -> 42800 | T24: =S24/1.12 -> 38214.286 | U24: =T24*12% -> 4585.7143 | V24: =T24+U24-S24 -> 0
A25: 0376 | B25: 45672 | C25: INV-2454 | D25: Ramona Tagum | E25: 80 | F25: Printing Bkwh P4 x 20 pages | G25: Cash | H25: UBP | J25: Add-Ons | K25: 80 | S25: =E25 -> 80 | T25: =S25/1.12 -> 71.428571 | U25: =T25*12% -> 8.5714286 | V25: =T25+U25-S25 -> 0
A26: 0377 | B26: 45672 | C26: INV-2453 | D26: BRANDSPEAKASIA INC. | E26: 19480.75 | F26: Use of address, Jan 7, 2025 to Dec 31, 2025 | G26: Bank Transfer | H26: UBP | I26: UB495547 | J26: Virtual Office | K26: 19480.75 | S26: =E26 -> 19480.75 | T26: =S26/1.12 -> 17393.527 | U26: =T26*12% -> 2087.2232 | V26: =T26+U26-S26 -> 0
A27: 0378 | D27: CANCELLED | J27: Meeting Rooms | S27: =E27 | T27: =S27/1.12 -> 0 | U27: =T27*12% -> 0 | V27: =T27+U27-S27 -> 0
A28: 0379 | B28: 45672 | C28: INV-2456 | D28: CoinAlpha Inc. | E28: 6900 | F28: Meeting Room 1, Jan 15, 2025, 11:00 am to 5:00 pm | G28: Maya Card | H28: UBP | J28: Add-Ons | K28: 6900 | O28: 226.58 | P28: =E28-O28 -> 6673.42 | Q28: =P28 -> 6673.42 | S28: =E28 -> 6900 | T28: =S28/1.12 -> 6160.7143 | U28: =T28*12% -> 739.28571 | V28: =T28+U28-S28 -> 0
A29: 0380 | B29: 45672 | C29: INV-2457 | D29: Cyril Cayasa | E29: 368 | F29: Printing P4 x 92 pages | G29: Maya QR Standee | H29: UBP | J29: Add-Ons | K29: 368 | O29: 1.64 | P29: =E29-O29 -> 366.36 | Q29: =P29 -> 366.36 | S29: =E29 -> 368 | T29: =S29/1.12 -> 328.57143 | U29: =T29*12% -> 39.428571 | V29: =T29+U29-S29 -> 0
A30: 0381 | B30: 45673 | C30: INV-2458 | D30: Norio-Olegario Consultancy Inc. | E30: 600 | F30: Printing B&W (P2x280 pages) ; Colored (P10x 4 pages) | G30: Maya QR Standee | H30: UBP | J30: Add-Ons | K30: 600 | O30: 2.68 | P30: =E30-O30 -> 597.32 | S30: =E30 -> 600 | T30: =S30/1.12 -> 535.71429 | U30: =T30*12% -> 64.285714 | V30: =T30+U30-S30 -> 0
A31: 0382 | B31: 45673 | C31: INV-2460 | D31: Cyril Cayasa | E31: 12 | F31: Printing B&W P2 x 6 | G31: Maya QR Standee | H31: UBP | J31: Add-Ons | K31: 12 | O31: 0.05 | P31: =E31-O31 -> 11.95 | S31: =E31 -> 12 | T31: =S31/1.12 -> 10.714286 | U31: =T31*12% -> 1.2857143 | V31: =T31+U31-S31 -> 0
A32: 0383 | B32: 45674 | C32: INV-2461 | D32: Leo Manabat | E32: 1680 | F32: Meeting room 3, 8 pm to 10 pm (w/ after hour access) | G32: Maya Card (Jan 16) | H32: UBP | J32: Meeting Rooms | K32: 1680 | O32: 55.17 | P32: =E32-O32 -> 1624.83 | Q32: =SUM(P30:P32) -> 2234.1 | S32: =E32 -> 1680 | T32: =S32/1.12 -> 1500 | U32: =T32*12% -> 180 | V32: =T32+U32-S32 -> 0
A33: 0384 | B33: 45674 | C33: INV-2393 | D33: QBE Group Shared Services Ltd- Philippine Branch | E33: 1703921.3 | F33: Private Office and Parking Rental January 2025 | G33: Check | H33: MBTC | I33: BPI 0001040674 | J33: Private Office | K33: 1792482.7 | L33: 88561.4 | M33: =K33-L33 -> 1703921.3 | N33: =E33-M33 -> 0.01 | S33: =K33 -> 1792482.7 | T33: 0 | U33: =T33*12% -> 0 | V33: 0
A34: 0385 | B34: 45674 | C34: INV-2455 | D34: SG ECOMMERCE CENTRE PHILIPPINES CORP. | E34: 4000 | F34: Virtual Office, Jan14, 2024 - Feb 13, 2025 | G34: Check | H34: UBP | I34: BDO 0000105976 | J34: Virtual Office | K34: 4000 | S34: =E34 -> 4000 | T34: =S34/1.12 -> 3571.4286 | U34: =T34*12% -> 428.57143 | V34: =T34+U34-S34 -> 0
A35: 0386 | B35: 45674 | C35: INV-2459 | D35: Zenko Enterprises OPC | E35: 15763.39 | F35: Use of Address, Feb 1, 2025 - Dec 31, 2025 | G35: Bank Transfer | H35: UBP | I35: S84967905 | J35: Virtual Office | K35: 16500 | L35: =K35/1.12*0.05 -> 736.60714 | M35: =K35-L35 -> 15763.393 | N35: =E35-M35 -> -0.0028571429 | S35: =K35 -> 16500 | T35: =S35/1.12 -> 14732.143 | U35: =T35*12% -> 1767.8571 | V35: =T35+U35-S35 -> 0
A36: 0387 | D36: CANCELLED | S36: =E36 | T36: =S36/1.12 -> 0 | U36: =T36*12% -> 0 | V36: =T36+U36-S36 -> 0
A37: 0388 | B37: 45677 | C37: INV-2337 | D37: DrinkAid Corp. | E37: 20903.31 | F37: Use of Address, November 3, 2024 to December 31, 2025 | G37: Maya Card | H37: UBP | J37: Virtual Office | K37: 20903.31 | O37: 686.4 | P37: =E37-O37 -> 20216.91 | S37: =E37 -> 20903.31 | T37: =S37/1.12 -> 18663.67 | U37: =T37*12% -> 2239.6404 | V37: =T37+U37-S37 -> 0
A38: 0389 | B38: 45677 | C38: INV-2370 | D38: Norio-Olegario Consultancy Inc. | E38: 24522.63 | F38: Use of Address and Locker rental, November 15, 2024 to December 31, 2025 | G38: Maya Card | H38: UBP | J38: Virtual Office | K38: 24522.63 | O38: 805.25 | P38: =E38-O38 -> 23717.38 | Q38: =SUM(P37:P38) -> 43934.29 | S38: =E38 -> 24522.63 | T38: =S38/1.12 -> 21895.205 | U38: =T38*12% -> 2627.4246 | V38: =T38+U38-S38 -> 0
A39: 0390 | D39: CANCELLED | S39: =E39 | T39: =S39/1.12 -> 0 | U39: =T39*12% -> 0 | V39: =T39+U39-S39 -> 0
A40: 0391 | B40: 45677 | C40: INV-2462 | D40: Radiance Image Consultancy and Training Inc. | E40: 18580.68 | F40: Use of Address, December 20, 2024 to December 31, 2025 | G40: Bank Transfer | H40: UBP | I40: UB495547 | J40: Meeting Rooms | K40: 18580.68 | S40: =E40 -> 18580.68 | T40: =S40/1.12 -> 16589.893 | U40: =T40*12% -> 1990.7871 | V40: =T40+U40-S40 -> 0
...

Sheet AR
A1: SI | B1: Date | C1: Client Name | D1: AR Amount | E1: Description | F1: Mode of Payment | G1: Cash/Check Deposit | H1: Remarks | J1: GROSS | K1: CWT | L1: TOTAL | M1: CC Fee | N1: Net Amount | P1: Gcash Fee | Q1: Net Amount
A2: 317 | B2: 45293 | C2: Kre8 Construction Services | D2: 3500 | E2: VO (Jan 1-31, 2024) | F2: Check | G2: UBP | H2: SB 0000887954
A3: 318 | B3: 45293 | C3: Cryo-Asia Philippines Corp. | D3: 3500 | E3: VO (Jan 1-31, 2024) | F3: Check | G3: UBP | H3: SB 0000483712
A4: 319 | B4: 45293 | C4: MB Areta ENgineering & Consultancy | D4: 3000 | E4: VO (Jan 2 - Feb 1, 2024) | F4: Check | G4: UBP | H4: BPI 1000045108
A5: 320 | B5: 45294 | C5: Jane Vacunua | D5: 4250 | E5: 50% DP for MR1 (Jan 13, 2024, 9a-5p) | F5: Bank Transfer | G5: UBP | H5: S1828540
A6: 321 | B6: 45295 | C6: Edward Guinto | D6: 1000 | E6: DP for MR3 (Jan 4, 2024, 12p-3p) | F6: Bank Transfer | G6: MBTC | H6: SN 359796
A7: 322 | B7: 45299 | C7: DrinkAid Corp | D7: 3500 | E7: VO (Jan 3 - Feb 2, 2024) | F7: Check | G7: UBP | H7: BDO 0000105736
A8: 323 | B8: 45299 | C8: Tohoku University | D8: 6000 | E8: 50% DP for MR3 Reservation on Jan 15-17, 2024, 8a-4p | F8: Cash | G8: MBTC
A9: 324 | B9: 45299 | C9: Werner Access Products Philippines Inc | D9: 7500 | E9: 50% DP for Feb 5 & 19, 2024 MR1 Reservation | F9: Maya Card | G9: UBP | M9: =D9*0.0285 -> 213.75 | N9: =D9-M9 -> 7286.25
A10: 325 | B10: 45308 | C10: Zenko Enterpries OPC | D10: 28660.71 | E10: VO (Feb 1, 2024 - Jan 31, 2025) | F10: Bank Transfer | G10: MBTC | H10: SN 000043
A11: 326 | B11: 45309 | C11: Cherry Love | D11: 1125 | E11: 50% DP for MR2, Jan 19, 2024, 3p-6p | F11: Bank Transfer | G11: UBP | H11: S9859862
A12: 327 | B12: 45310 | C12: Griffinstone Inc | D12: 15261 | E12: Access Card of Sir Miel | F12: Check | G12: UBP | H12: CB 0009648814
A13: 328 | B13: 45316 | C13: Health Channels Innovators Inc | D13: 3343.75 | E13: VO (Jan 24 - Feb 23, 2024) | F13: Check | G13: UBP | H13: CB 0000284599
A14: 329 | B14: 45316 | C14: 9 Life Lessons Inc | D14: 36000 | E14: VO (Feb 1, 2024 - Jan 31, 2025) | F14: Check | G14: UBP | H14: BPI 0002187622
A15: 330 | B15: 45316 | C15: Daniel Valerio | D15: 10000 | E15: Event Space 2 (Jan 28, 2024. 3p-7p) | F15: Cash
A16: 331 | B16: 45316 | C16: Alexander Uy | D16: 6250 | E16: 50% DP for Event Space 2, Feb 17, 2024. 3p-7p | F16: Check | G16: UBP | H16: BDO 0000119008
A17: 332 | B17: 45323 | C17: Innoprince Inc | D17: 3000 | E17: VO (Feb 1-29, 2024) | F17: Check (BT From SI) | G17: UBP
A18: 333 | B18: 45327 | C18: Werner Access Products Philippines Inc | D18: 7500 | E18: 50% DP for MR1, Mar 4 & Mar 25, 2024 | F18: Maya Card | G18: UBP | M18: =D18*0.0285 -> 213.75 | N18: =D18-M18 -> 7286.25
A19: 334 | B19: 45327 | C19: MB Areta ENgineering & Consultancy | D19: 3000 | E19: VO (Feb 2 - Mar 1, 2024) | F19: Check | G19: UBP | H19: BPI 100045109
A20: 335 | B20: 45327 | C20: DrinkAid Corp | D20: 3500 | E20: VO (Feb 3 - Mar 2, 2024) | F20: Check | G20: UBP | H20: BDO 0000105732
A21: 335 | B21: 45331 | C21: Offsite Solutions Inc | D21: 2300 | E21: 50% DP for MR3, Feb 15, 2024. 10a-7p | F21: Bank Transfer | G21: UBP | H21: UB476294
A22: 336 | B22: 45334 | C22: Dania Tablizo | D22: 6500 | E22: 50% DP for Event Sapce 2, Mar 2, 2024. 1p-5p | F22: Bank Transfer | G22: UBP | H22: S20646478
A23: 337 | B23: 45339 | C23: Alexander Uy | D23: 6250 | E23: Full Payment for Event Space 2, Feb 17, 2024, 1p-8p | F23: Check | G23: UBP | H23: BDO 0000119011
A24: 338 | B24: 45341 | C24: E.Gonzales Law Office | D24: 3500 | E24: VO (Feb 15 - Mar 14, 2024) | F24: Check | G24: UBP | H24: BDO 0001149553
A25: 339 | B25: 45341 | C25: Goetz Moving and Storage Inc. | D25: 7500 | E25: 50% DP for MR1, Mar 6 & 8, 2024, 9a-5p | F25: Bank Transfer | G25: UBP | H25: UB648449
A26: 340 | B26: 45349 | C26: Insightscs | D26: 6000 | E26: DP for MR 1 - Feb 28, 2024, 9am - 3pm | F26: Bank Transfer | G26: UBP | H26: UB1057342
A27: 341 | B27: 45355 | C27: Werner Access Products Philippines Inc | D27: 7500 | E27: 50% DP for MR 1, Apr 8 and Apr 29, 2024 | F27: Maya Card | G27: UBP | M27: =D27*0.0285 -> 213.75 | N27: =D27-M27 -> 7286.25
A28: 342 | B28: 45355 | C28: MB Areta ENgineering & Consultancy | D28: 3000 | E28: VO (Mar 7 - April 1, 2024) | F28: Check | G28: UBP | H28: BPI 1000045110
A29: 343 | B29: 45355 | C29: KRE8 Construction Services | D29: 3500 | E29: VO (Mar 1 - Mar 31, 2024) | F29: Check | G29: UBP | H29: SB 0000887956
A30: 344 | B30: 45355 | C30: DrinkAid Corp | D30: 3500 | E30: VO (Mar 3 - April 2, 2024) | F30: Check | G30: UBP | H30: BDO 0000105738
A31: 345 | B31: 45351 | C31: Health Channels Innovators, Inc. | D31: 3343.75 | E31: VO (Feb 24 - Mar 23, 2024) | F31: Check | G31: UBP | H31: CTBC 0000284600
A32: 346 | B32: 45357 | C32: Profitable Personnel Pty Ltd | D32: 3000 | E32: VO (Mar 1 - Mar 31, 2024) | F32: Check | G32: UBP | H32: BDO 0000011874
A33: 347 | B33: 45369 | C33: E Gonzales Law Office | D33: 3500 | E33: VO (Mar 15, 2024 - April 14, 2024) | F33: Check | G33: UBP | H33: BDO 0001149554
A34: 348 | B34: 45376 | C34: Health Channels Innovators Inc. | D34: 3343.75 | E34: VO (Mar 24, 2024 - April 23, 2024) | F34: Check | G34: UBP | H34: CTBC 0000284601 | J34: 3500 | K34: =J34/1.12*0.05 -> 156.25 | L34: =J34-K34 -> 3343.75
A35: 349 | B35: 45384 | C35: Galleon Sciences R&D Corporation | D35: 3500 | E35: VO (Apr 5, 2024 - May 4, 2024) | F35: Check | G35: UBP | H35: BDO 0000620240
A36: 350 | B36: 45384 | C36: Timedly Solutions, Inc. | D36: 3500 | E36: VO (Apr 1, 2024 - Apr 30, 2024) | F36: Check | G36: UBP | H36: SB 0000509601
A37: 351 | B37: 45384 | C37: MBAreta Engineering & Consultancy Services | D37: 3000 | E37: VO (Apr 2, 2024 - May 1, 2024) | F37: Check | G37: UBP | H37: BPI 1000045111
A38: 352 | B38: 45384 | C38: Kre8 Construction Services | D38: 3500 | E38: VO (Apr 1, 2024 - Apr 30, 2024) | F38: Check | G38: UBP | H38: SB 0000887957
A39: 353 | B39: 45386 | C39: Anytime Fitness Evia | D39: 1995.71 | E39: 50% DP for Meeting Room 3, April 8, 2024 (9am to 5pm) | F39: Bank Transfer | G39: MBTC | H39: SN000101
A40: 354 | B40: 45386 | C40: Nutrition Center of the Philippines | D40: 4394.64 | E40: Meeting Room 3 (March 18, 2024, 9am - 6pm) | F40: Bank Transfer | G40: UBP | H40: UB14802 | J40: 4600 | K40: =J40/1.12*0.05 -> 205.35714 | L40: =J40-K40 -> 4394.6429
...

Sheet SI Amendment
A1: SI | B1: Date | C1: Invoice Number | D1: Client Name | E1: OR Amount | F1: Description | G1: Mode of Payment | H1: Cash / Check Deposit | I1: Remarks | J1: Type of Service | K1: GROSS | L1: CWT | M1: TOTAL | O1: CC Fee/Charge | P1: Net Amount | Q1: Checking | S1: GROSS AMOUTN | T1: NET AMOUNT | U1: VAT AMOUNT | W1: GROSS AMOUNT | X1: NET AMOUNT | Y1: VAT AMOUNT
A2: 0353 | B2: 45660 | C2: INV-2426 | D2: Timedly Solutions, Inc. | E2: 3500 | F2: Virtual Office, Jan 1, 2025 - Jan 31, 2025 | G2: Check | H2: UBP | I2: Security Bank 0000509610 | J2: Virtual Office | S2: =E2 -> 3500 | T2: =S2/1.12 -> 3125 | U2: =T2*0.12 -> 375 | W2: =E2 -> 3500 | X2: =W2/1.12 -> 3125 | Y2: =X2*0.12 -> 375
A3: 0354 | B3: 45663 | C3: INV-2435 | D3: Intertool Precision Group Inc | E3: 2100 | F3: Meeting Room 3, 3:00 pm to 6:00 pm | G3: Maya QR Standee | H3: UBP | J3: Meeting Rooms | O3: 9.38 | P3: =E3-O3 -> 2090.62 | S3: =E3 -> 2100 | T3: =S3/1.12 -> 1875 | U3: =T3*0.12 -> 225 | W3: =E3 -> 2100 | X3: =W3/1.12 -> 1875 | Y3: =X3*0.12 -> 225
A4: 0355 | D4: CANCELLED | S4: =E4 | T4: =S4/1.12 -> 0 | U4: =T4*0.12 -> 0 | W4: =E4 | X4: =W4/1.12 -> 0 | Y4: =X4*0.12 -> 0
A5: 0356 | B5: 45664 | C5: INV-2437 | D5: Bluvision Surveillance and Analytics Inc. | E5: 4500 | F5: Meeting Room 1, Jan 8, 2025, 9:00 am to 1:00 pm | G5: Maya QR Standee | H5: UBP | J5: Meeting Rooms | O5: 20.09 | P5: =E5-O5 -> 4479.91 | S5: =E5 -> 4500 | T5: =S5/1.12 -> 4017.8571 | U5: =T5*0.12 -> 482.14286 | W5: =E5 -> 4500 | X5: =W5/1.12 -> 4017.8571 | Y5: =X5*0.12 -> 482.14286
A6: 0357 | B6: 45665 | C6: INV-2467 | D6: Lawrence Alexander | E6: 20 | F6: Printing | G6: Maya QR Standee | H6: UBP | J6: Add-Ons | O6: 0.09 | P6: =E6-O6 -> 19.91 | S6: =E6 -> 20 | T6: =S6/1.12 -> 17.857143 | U6: =T6*0.12 -> 2.1428571 | W6: =E6 -> 20 | X6: =W6/1.12 -> 17.857143 | Y6: =X6*0.12 -> 2.1428571
A7: 0358 | B7: 45665 | C7: INV-2438 | D7: Limuel Libres | E7: 350 | F7: Wholeday Flypass (Student) | G7: Cash | H7: MBTC | J7: Walk-Ins | S7: =E7 -> 350 | T7: =S7/1.12 -> 312.5 | U7: =T7*0.12 -> 37.5 | W7: =E7 -> 350 | X7: =W7/1.12 -> 312.5 | Y7: =X7*0.12 -> 37.5
A8: 0359 | B8: 45666 | C8: INV-2441 | D8: Margarita Bariring | E8: 5500 | F8: Monthly Flypass | G8: Maya Card | H8: UBP | J8: Monthly Membership | O8: 180.6 | P8: =E8-O8 -> 5319.4 | S8: =E8 -> 5500 | T8: =S8/1.12 -> 4910.7143 | U8: =T8*0.12 -> 589.28571 | W8: =E8 -> 5500 | X8: =W8/1.12 -> 4910.7143 | Y8: =X8*0.12 -> 589.28571
A9: 0360 | B9: 45666 | C9: INV-2442 | D9: MARRO FASHION STYLING STUDIO | E9: 2400 | F9: Meeting Room 2, 9:30 am to 12:00 nn | G9: Maya Card | H9: UBP | J9: Meeting Rooms | O9: 78.81 | P9: =E9-O9 -> 2321.19 | S9: =E9 -> 2400 | T9: =S9/1.12 -> 2142.8571 | U9: =T9*0.12 -> 257.14286 | W9: =E9 -> 2400 | X9: =W9/1.12 -> 2142.8571 | Y9: =X9*0.12 -> 257.14286
A10: 0361 | B10: 45666 | C10: INV-2443 | D10: F.A BAUTISTA & PARTNERS | E10: 5500 | F10: Meeting Room 3, January 10, 2025, 8:30 am to 5:00 pm | G10: Maya QR Standee | H10: UBP | J10: Meeting Rooms | O10: 24.55 | P10: =E10-O10 -> 5475.45 | Q10: =SUM(P8:P10) -> 13116.04 | S10: =E10 -> 5500 | T10: =S10/1.12 -> 4910.7143 | U10: =T10*0.12 -> 589.28571 | W10: =E10 -> 5500 | X10: =W10/1.12 -> 4910.7143 | Y10: =X10*0.12 -> 589.28571
A11: 0362 | B11: 45666 | C11: INV-2436 | D11: Moom Health Services Corp | E11: 4000 | F11: Virtual Office, Jan 4, 2025 - Feb 3, 2025 | G11: Check | H11: UBP | I11: BDO 0000158359 | J11: Virtual Office | S11: =E11 -> 4000 | T11: =S11/1.12 -> 3571.4286 | U11: =T11*0.12 -> 428.57143 | W11: =E11 -> 4000 | X11: =W11/1.12 -> 3571.4286 | Y11: =X11*0.12 -> 428.57143
A12: 0363 | B12: 45667 | C12: INV-2468 | D12: Lawrence Alexander | E12: 10 | F12: Printing | G12: Maya QR Standee | H12: UBP | J12: Add-Ons | O12: 0.04 | P12: =E12-O12 -> 9.96 | S12: =E12 -> 10 | T12: =S12/1.12 -> 8.9285714 | U12: =T12*0.12 -> 1.0714286 | W12: =E12 -> 10 | X12: =W12/1.12 -> 8.9285714 | Y12: =X12*0.12 -> 1.0714286
A13: 0364 | B13: 45667 | C13: INV-2445 | D13: Kevin Carmelina | E13: 1600 | F13: Meeting Room 2, 1:00 pm to 3:00 pm | G13: Maya Card | H13: UBP | J13: Meeting Rooms | O13: 52.54 | P13: =E13-O13 -> 1547.46 | S13: =E13 -> 1600 | T13: =S13/1.12 -> 1428.5714 | U13: =T13*0.12 -> 171.42857 | W13: =E13 -> 1600 | X13: =W13/1.12 -> 1428.5714 | Y13: =X13*0.12 -> 171.42857
A14: 0365 | D14: CANCELLED | S14: =E14 | T14: =S14/1.12 -> 0 | U14: =T14*0.12 -> 0 | W14: =E14 | X14: =W14/1.12 -> 0 | Y14: =X14*0.12 -> 0
A15: 0366 | D15: CANCELLED | S15: =E15 | T15: =S15/1.12 -> 0 | U15: =T15*0.12 -> 0 | W15: =E15 | X15: =W15/1.12 -> 0 | Y15: =X15*0.12 -> 0
A16: 0367 | B16: 45667 | C16: INV-2446 | D16: Paolo De Asis | E16: 600 | F16: Wholeday Flypass | G16: Cash | H16: MBTC | S16: =E16 -> 600 | T16: =S16/1.12 -> 535.71429 | U16: =T16*0.12 -> 64.285714 | W16: =E16 -> 600 | X16: =W16/1.12 -> 535.71429 | Y16: =X16*0.12 -> 64.285714
A17: 0368 | B17: 45667 | C17: INV-2447 | D17: Brey Reyes | E17: 2400 | F17: Meeting Room 2, 4:30 pm to 6:00 pm | G17: Maya Card | H17: UBP | J17: Walk-Ins | O17: 78.81 | P17: =E17-O17 -> 2321.19 | Q17: =P13+P17+P19+[1]AR!N127 -> #ERROR! | S17: =E17 -> 2400 | T17: =S17/1.12 -> 2142.8571 | U17: =T17*0.12 -> 257.14286 | W17: =E17 -> 2400 | X17: =W17/1.12 -> 2142.8571 | Y17: =X17*0.12 -> 257.14286
A18: 0369 | B18: 45668 | C18: INV-2450 | D18: AIMS Industrial Supplies | E18: 84400 | F18: Meeting Room 1, 2 and 3, February 3-7, 2025 | G18: AR 435 (42200) Maya Card (42200) | H18: UBP | I18: UB1297258 | J18: Meeting Rooms | O18: 1385.72 | P18: =42200-O18 -> 40814.28 | Q18: =42200-O18 -> 40814.28 | S18: =E18 -> 84400 | T18: =S18/1.12 -> 75357.143 | U18: =T18*0.12 -> 9042.8571 | W18: =E18 -> 84400 | X18: =W18/1.12 -> 75357.143 | Y18: =X18*0.12 -> 9042.8571
A19: 0370 | B19: 45670 | C19: INV-2448 | D19: E Gonzales Law Office | E19: 17322.63 | F19: Use of Address, Jan 15, 2025 to Dec 31, 2025 | G19: Maya Card (Jan 10) | H19: UBP | J19: Virtual Office | O19: 568.83 | P19: =E19-O19 -> 16753.8 | S19: =E19 -> 17322.63 | T19: =S19/1.12 -> 15466.634 | U19: =T19*0.12 -> 1855.9961 | W19: =E19 -> 17322.63 | X19: =W19/1.12 -> 15466.634 | Y19: =X19*0.12 -> 1855.9961
A20: 0371 | B20: 45670 | C20: INV-2452 | D20: Arkiya Francine Orosco | E20: 2400 | F20: Meeting Room 2, Jan 13, 2025, 9:00 am to 12:00 pm | G20: Cash | H20: MBTC | J20: Meeting Rooms | S20: =E20 -> 2400 | T20: =S20/1.12 -> 2142.8571 | U20: =T20*0.12 -> 257.14286 | W20: =E20 -> 2400 | X20: =W20/1.12 -> 2142.8571 | Y20: =X20*0.12 -> 257.14286
A21: 0372 | D21: CANCELLED | S21: =E21 | T21: =S21/1.12 -> 0 | U21: =T21*0.12 -> 0 | W21: =E21 | X21: =W21/1.12 -> 0 | Y21: =X21*0.12 -> 0
A22: 0373 | B22: 45670 | C22: INV-2451 | D22: Sightechs Corporation | E22: 24000 | F22: Virtual Office, Jan 1, 2025 - Jun 30, 2025 | G22: Bank Transfer | H22: UBP | I22: UB1060687 | J22: Virtual Office | S22: =E22 -> 24000 | T22: =S22/1.12 -> 21428.571 | U22: =T22*0.12 -> 2571.4286 | W22: =E22 -> 24000 | X22: =W22/1.12 -> 21428.571 | Y22: =X22*0.12 -> 2571.4286
A23: 0374 | B23: 45671 | C23: INV-2432/INV-2433/INV-2428/INV-2429/INV-2430/INV-2431 | D23: iHub Solutions (Philippines) Inc. | E23: 127841.68 | F23: Meeting Room 2, 7am to 4pm, Jan (full) , Feb - Apr (DP) & Locker Rental (jan-Apr) & Virtual Office (Jan 20 - Dec 31, 2025) | G23: Bank Transfer | H23: UBP | I23: UB799581 | J23: Meeting Rooms | S23: =E23 -> 127841.68 | T23: =S23/1.12 -> 114144.36 | U23: =T23*0.12 -> 13697.323 | W23: =E23 -> 127841.68 | X23: =W23/1.12 -> 114144.36 | Y23: =X23*0.12 -> 13697.323
A24: 0375 | B24: 45671 | C24: INV-2427/INV-2425 | D24: Recruitgo Philippines Inc. | E24: =8500+34300 -> 42800 | F24: Meeting Room 1 rental, Jan 9, 16, 23, 30 & Locker Rental (Jan 2025) | G24: Bank Transfer | H24: UBP | I24: UB1200210 | J24: Meeting Rooms | S24: =E24 -> 42800 | T24: =S24/1.12 -> 38214.286 | U24: =T24*0.12 -> 4585.7143 | W24: =E24 -> 42800 | X24: =W24/1.12 -> 38214.286 | Y24: =X24*0.12 -> 4585.7143
A25: 0376 | B25: 45672 | C25: INV-2454 | D25: Ramona Tagum | E25: 80 | F25: Printing Bkwh P4 x 20 pages | G25: Cash | H25: UBP | J25: Add-Ons | S25: =E25 -> 80 | T25: =S25/1.12 -> 71.428571 | U25: =T25*0.12 -> 8.5714286 | W25: =E25 -> 80 | X25: =W25/1.12 -> 71.428571 | Y25: =X25*0.12 -> 8.5714286
A26: 0377 | B26: 45672 | C26: INV-2453 | D26: BRANDSPEAKASIA INC. | E26: 19480.75 | F26: Use of address, Jan 7, 2025 to Dec 31, 2025 | G26: Bank Transfer | H26: UBP | I26: UB495547 | J26: Virtual Office | S26: =E26 -> 19480.75 | T26: =S26/1.12 -> 17393.527 | U26: =T26*0.12 -> 2087.2232 | W26: =E26 -> 19480.75 | X26: =W26/1.12 -> 17393.527 | Y26: =X26*0.12 -> 2087.2232
A27: 0378 | D27: CANCELLED | J27: Meeting Rooms | S27: =E27 | T27: =S27/1.12 -> 0 | U27: =T27*0.12 -> 0 | W27: =E27 | X27: =W27/1.12 -> 0 | Y27: =X27*0.12 -> 0
A28: 0379 | B28: 45672 | C28: INV-2456 | D28: CoinAlpha Inc. | E28: 6900 | F28: Meeting Room 1, Jan 15, 2025, 11:00 am to 5:00 pm | G28: Maya Card | H28: UBP | J28: Add-Ons | O28: 226.58 | P28: =E28-O28 -> 6673.42 | Q28: =P28 -> 6673.42 | S28: =E28 -> 6900 | T28: =S28/1.12 -> 6160.7143 | U28: =T28*0.12 -> 739.28571 | W28: =E28 -> 6900 | X28: =W28/1.12 -> 6160.7143 | Y28: =X28*0.12 -> 739.28571
A29: 0380 | B29: 45672 | C29: INV-2457 | D29: Cyril Cayasa | E29: 368 | F29: Printing P4 x 92 pages | G29: Maya QR Standee | H29: UBP | J29: Add-Ons | O29: 1.64 | P29: =E29-O29 -> 366.36 | Q29: =P29 -> 366.36 | S29: =E29 -> 368 | T29: =S29/1.12 -> 328.57143 | U29: =T29*0.12 -> 39.428571 | W29: =E29 -> 368 | X29: =W29/1.12 -> 328.57143 | Y29: =X29*0.12 -> 39.428571
A30: 0381 | B30: 45673 | C30: INV-2458 | D30: Norio-Olegario Consultancy Inc. | E30: 600 | F30: Printing B&W (P2x280 pages) ; Colored (P10x 4 pages) | G30: Maya QR Standee | H30: UBP | J30: Add-Ons | O30: 2.68 | P30: =E30-O30 -> 597.32 | S30: =E30 -> 600 | T30: =S30/1.12 -> 535.71429 | U30: =T30*0.12 -> 64.285714 | W30: =E30 -> 600 | X30: =W30/1.12 -> 535.71429 | Y30: =X30*0.12 -> 64.285714
A31: 0382 | B31: 45673 | C31: INV-2460 | D31: Cyril Cayasa | E31: 12 | F31: Printing B&W P2 x 6 | G31: Maya QR Standee | H31: UBP | J31: Add-Ons | O31: 0.05 | P31: =E31-O31 -> 11.95 | S31: =E31 -> 12 | T31: =S31/1.12 -> 10.714286 | U31: =T31*0.12 -> 1.2857143 | W31: =E31 -> 12 | X31: =W31/1.12 -> 10.714286 | Y31: =X31*0.12 -> 1.2857143
A32: 0383 | B32: 45674 | C32: INV-2461 | D32: Leo Manabat | E32: 1680 | F32: Meeting room 3, 8 pm to 10 pm (w/ after hour access) | G32: Maya Card (Jan 16) | H32: UBP | J32: Meeting Rooms | O32: 55.17 | P32: =E32-O32 -> 1624.83 | Q32: =SUM(P30:P32) -> 2234.1 | S32: =E32 -> 1680 | T32: =S32/1.12 -> 1500 | U32: =T32*0.12 -> 180 | W32: =E32 -> 1680 | X32: =W32/1.12 -> 1500 | Y32: =X32*0.12 -> 180
A33: 0384 | B33: 45674 | C33: INV-2393 | D33: QBE Group Shared Services Ltd- Philippine Branch | E33: 1703921.3 | F33: Private Office and Parking Rental January 2025 | G33: Check | H33: MBTC | I33: BPI 0001040674 | J33: Private Office | K33: 1792482.7 | L33: 88561.4 | M33: =K33-L33 -> 1703921.3 | N33: =E33-M33 -> 0.01 | S33: =K33 -> 1792482.7 | T33: 0 | U33: =T33*0.12 -> 0 | W33: 198377.52 | X33: =W33/1.12 -> 177122.79 | Y33: =X33*0.12 -> 21254.734
A34: 0385 | B34: 45674 | C34: INV-2455 | D34: SG ECOMMERCE CENTRE PHILIPPINES CORP. | E34: 4000 | F34: Virtual Office, Jan14, 2024 - Feb 13, 2025 | G34: Check | H34: UBP | I34: BDO 0000105976 | J34: Virtual Office | S34: =E34 -> 4000 | T34: =S34/1.12 -> 3571.4286 | U34: =T34*0.12 -> 428.57143 | W34: =E34 -> 4000 | X34: =W34/1.12 -> 3571.4286 | Y34: =X34*0.12 -> 428.57143
A35: 0386 | B35: 45674 | C35: INV-2459 | D35: Zenko Enterprises OPC | E35: 15763.39 | F35: Use of Address, Feb 1, 2025 - Dec 31, 2025 | G35: Bank Transfer | H35: UBP | I35: S84967905 | J35: Virtual Office | K35: 16500 | L35: =K35/1.12*0.05 -> 736.60714 | M35: =K35-L35 -> 15763.393 | N35: =E35-M35 -> -0.0028571429 | S35: =K35 -> 16500 | T35: =S35/1.12 -> 14732.143 | U35: =T35*0.12 -> 1767.8571 | W35: 16500 | X35: =W35/1.12 -> 14732.143 | Y35: =X35*0.12 -> 1767.8571
A36: 0387 | D36: CANCELLED | S36: =E36 | T36: =S36/1.12 -> 0 | U36: =T36*0.12 -> 0 | W36: =E36 | X36: =W36/1.12 -> 0 | Y36: =X36*0.12 -> 0
A37: 0388 | B37: 45677 | C37: INV-2337 | D37: DrinkAid Corp. | E37: 20903.31 | F37: Use of Address, November 3, 2024 to December 31, 2025 | G37: Maya Card | H37: UBP | J37: Virtual Office | O37: 686.4 | P37: =E37-O37 -> 20216.91 | S37: =E37 -> 20903.31 | T37: =S37/1.12 -> 18663.67 | U37: =T37*0.12 -> 2239.6404 | W37: =E37 -> 20903.31 | X37: =W37/1.12 -> 18663.67 | Y37: =X37*0.12 -> 2239.6404
A38: 0389 | B38: 45677 | C38: INV-2370 | D38: Norio-Olegario Consultancy Inc. | E38: 24522.63 | F38: Use of Address and Locker rental, November 15, 2024 to December 31, 2025 | G38: Maya Card | H38: UBP | J38: Virtual Office | O38: 805.25 | P38: =E38-O38 -> 23717.38 | Q38: =SUM(P37:P38) -> 43934.29 | S38: =E38 -> 24522.63 | T38: =S38/1.12 -> 21895.205 | U38: =T38*0.12 -> 2627.4246 | W38: =E38 -> 24522.63 | X38: =W38/1.12 -> 21895.205 | Y38: =X38*0.12 -> 2627.4246
A39: 0390 | D39: CANCELLED | S39: =E39 | T39: =S39/1.12 -> 0 | U39: =T39*0.12 -> 0 | W39: =E39 | X39: =W39/1.12 -> 0 | Y39: =X39*0.12 -> 0
A40: 0391 | B40: 45677 | C40: INV-2462 | D40: Radiance Image Consultancy and Training Inc. | E40: 18580.68 | F40: Use of Address, December 20, 2024 to December 31, 2025 | G40: Bank Transfer | H40: UBP | I40: UB495547 | J40: Meeting Rooms | S40: =E40 -> 18580.68 | T40: =S40/1.12 -> 16589.893 | U40: =T40*0.12 -> 1990.7871 | W40: =E40 -> 18580.68 | X40: =W40/1.12 -> 16589.893 | Y40: =X40*0.12 -> 1990.7871 | Z40: 2024 Sales but not reported
...

Sheet Xero Purchases G 2025
A1: Xero Purchases Goods 2025
A2: Shirefolk Ventures, Inc.
A3: For the period 1 January 2025 to 31 March 2025
A5: Tax Rate Name contains VAT on Purchases (Capital Goods), VAT on Purchases (Goods Not Qual for Input Tax), VAT on Purchases (Goods)
A7: Date | B7: Source | C7: Contact | D7: Description | E7: Reference | F7: Debit | G7: Credit | H7: Gross | I7: Net | J7: Tax | K7: Account
A9: VAT on Purchases (Goods Not Qual for Input Tax)
A10: 45691 | B10: Spend Money | C10: Grand Union Supermarket Inc. | D10: Grand Union Supermarket Inc. - Pantry supplies- Vat exempt | E10: PCF 2359 | F10: 168 | G10: 0 | H10: 168 | I10: 168 | J10: 0 | K10: Office and Pantry Supplies
A11: 45699 | B11: Spend Money | C11: Grand Union Supermarket Inc. | D11: Grand Union Supermarket Inc. - Pantry and office Supplies- Vat exempt | E11: PCF 2371 | F11: 168 | G11: 0 | H11: 168 | I11: 168 | J11: 0 | K11: Office and Pantry Supplies
A12: 45703 | B12: Spend Money | C12: Grand Union Supermarket Inc. | D12: Grand Union Supermarket Inc. - Pantry Supplies- Vat exempt | E12: PCF 2382 | F12: 168 | G12: 0 | H12: 168 | I12: 168 | J12: 0 | K12: Office and Pantry Supplies
A14: 45719 | B14: Spend Money | C14: Edwin C. Nopuente Prop. | D14: Edwin C. Nopuente Prop. - 4 gallons purified water | E14: PCF 2405 | F14: 120 | G14: 0 | H14: 120 | I14: 120 | J14: 0 | K14: Office and Pantry Supplies
A15: 45728 | B15: Spend Money | C15: Edwin C. Nopuente Prop. | D15: Edwin C. Nopuente Prop. - water - 12 bottles | E15: PCF- 2430 | F15: 360 | G15: 0 | H15: 360 | I15: 360 | J15: 0 | K15: Office and Pantry Supplies
A16: 45728 | B16: Spend Money | C16: Grand Union Supermarket Inc. | D16: Grand Union Supermarket Inc. - Pantry Supplies- Vat exempt | E16: PCF- 2431 | F16: 84 | G16: 0 | H16: 84 | I16: 84 | J16: 0 | K16: Office and Pantry Supplies
A17: 45729 | B17: Spend Money | C17: Edwin C. Nopuente Prop. | D17: Edwin C. Nopuente Prop. - Water- 9 bottles | E17: PCF- 2432 | F17: 270 | G17: 0 | H17: 270 | I17: 270 | J17: 0 | K17: Office and Pantry Supplies
A18: 45730 | B18: Spend Money | C18: Edwin C. Nopuente Prop. | D18: Edwin C. Nopuente Prop. - Water | E18: PCF- 2434 | F18: 240 | G18: 0 | H18: 240 | I18: 240 | J18: 0 | K18: Office and Pantry Supplies
A19: 45733 | B19: Spend Money | C19: Edwin C. Nopuente Prop. | D19: Edwin C. Nopuente Prop. - Water | E19: PCF- 2435 | F19: 180 | G19: 0 | H19: 180 | I19: 180 | J19: 0 | K19: Office and Pantry Supplies
A20: 45734 | B20: Spend Money | C20: Grand Union Supermarket Inc. | D20: Grand Union Supermarket Inc. - Pantry Supplies- Vat Exempt | E20: PCF- 2437 | F20: 168 | G20: 0 | H20: 168 | I20: 168 | J20: 0 | K20: Office and Pantry Supplies
A21: 45736 | B21: Spend Money | C21: Edwin C. Nopuente Prop. | D21: Edwin C. Nopuente Prop. - Water | E21: PCF- 2439 | F21: 390 | G21: 0 | H21: 390 | I21: 390 | J21: 0 | K21: Office and Pantry Supplies
A22: 45737 | B22: Spend Money | C22: Grand Union Supermarket Inc. | D22: Grand Union Supermarket Inc. - Pantry Supplies- VAt exempt | E22: PCF- 2440 | F22: 84 | G22: 0 | H22: 84 | I22: 84 | J22: 0 | K22: Office and Pantry Supplies
... A30: 45747 | B30: Spend Money | C30: Edwin C. Nopuente Prop. | D30: Edwin C. Nopuente Prop. - Water | E30: PCF- 2452 | F30: 120 | G30: 0 | H30: 120 | I30: 120 | J30: 0 | K30: Office and Pantry Supplies
A31: Total VAT on Purchases (Goods Not Qual for Input Tax) | F31: 3774 | G31: 0 | H31: 3774 | I31: 3774 | J31: 0
A33: VAT on Purchases (Goods)
A34: 45663 | B34: Spend Money | C34: Grand Union Supermarket Inc. | D34: Grand Union Supermarket Inc. - Pantry Supplies | E34: PCF 2311 | F34: 1903.53 | G34: 0 | H34: 2131.95 | I34: 1903.53 | J34: 228.42 | K34: Office and Pantry Supplies
A35: 45665 | B35: Payable Invoice | C35: HEBREWSKAPE TRADING INC. | D35: HEBREWSKAPE TRADING INC. - Coffee Beans (Hazel Nut 13 kg.) Jan 2025 | E35: UBP-0125-922 | F35: 7670 | G35: 0 | H35: 8590.4 | I35: 7670 | J35: 920.4 | K35: Office and Pantry Supplies
A36: 45665 | B36: Spend Money | C36: Grand Union Supermarket Inc. | D36: Grand Union Supermarket Inc. - Pantry Supplies | E36: PCF 2314 | F36: 1710.89 | G36: 0 | H36: 1916.2 | I36: 1710.89 | J36: 205.31 | K36: Office and Pantry Supplies
A37: 45671 | B37: Spend Money | C37: Grand Union Supermarket Inc. | D37: Grand Union Supermarket Inc. - Pantry Supplies | E37: PCF 2322 | F37: 1016.07 | G37: 0 | H37: 1138 | I37: 1016.07 | J37: 121.93 | K37: Office and Pantry Supplies
A38: 45672 | B38: Spend Money | C38: Grand Union Supermarket Inc. | D38: Grand Union Supermarket Inc. - Pantry Supplies | E38: PCF 2323 | F38: 1206.21 | G38: 0 | H38: 1350.95 | I38: 1206.21 | J38: 144.74 | K38: Office and Pantry Supplies
A39: 45673 | B39: Spend Money | C39: Grand Union Supermarket Inc. | D39: Grand Union Supermarket Inc. - Pantry supplies | E39: PCF 2331 | F39: 964.73 | G39: 0 | H39: 1080.5 | I39: 964.73 | J39: 115.77 | K39: Office and Pantry Supplies
A40: 45673 | B40: Spend Money | C40: Grand Union Supermarket Inc. | D40: Grand Union Supermarket Inc. - A4 Bond Paper 2 reams | E40: PCF 2332 | F40: 478.57 | G40: 0 | H40: 536 | I40: 478.57 | J40: 57.43 | K40: Office and Pantry Supplies
A41: 45673 | B41: Spend Money | C41: Shakey's Pizza Asia Ventures Inc | D41: Shakey's Pizza Asia Ventures Inc - Food for Mancom meeting Jan 15 2025 | E41: PCF 2329 | F41: 900.89 | G41: 0 | H41: 1009 | I41: 900.89 | J41: 108.11 | K41: Meals Expense
A42: 45677 | B42: Spend Money | C42: Grand Union Supermarket Inc. | D42: Grand Union Supermarket Inc. - Pantry supplies | E42: PCF 2339 | F42: 2358.53 | G42: 0 | H42: 2641.55 | I42: 2358.53 | J42: 283.02 | K42: Office and Pantry Supplies
A43: 45679 | B43: Spend Money | C43: Grand Union Supermarket Inc. | D43: Grand Union Supermarket Inc. - Pantry Supplies | E43: PCF 2342 | F43: 1573.13 | G43: 0 | H43: 1761.9 | I43: 1573.13 | J43: 188.77 | K43: Office and Pantry Supplies
A44: 45681 | B44: Spend Money | C44: Grand Union Supermarket Inc. | D44: Grand Union Supermarket Inc. - Office Supplies | E44: PCF 2343 | F44: 89.29 | G44: 0 | H44: 100 | I44: 89.29 | J44: 10.71 | K44: Office and Pantry Supplies
A45: 45685 | B45: Spend Money | C45: Grand Union Supermarket Inc. | D45: Grand Union Supermarket Inc. - Pantry Supplies | E45: PCF 2350 | F45: 1557.32 | G45: 0 | H45: 1744.2 | I45: 1557.32 | J45: 186.88 | K45: Office and Pantry Supplies
... A89: 45747 | B89: Payable Invoice | C89: Puregold Price Club Inc.- GMA Cavite | D89: Puregold Price Club Inc.- GMA Cavite - Marketing Expense for July 2024 Ref: SI 127-009-00290911 | E89: UBP-0724-800 (3) | F89: 2036.61 | G89: 0 | H89: 2281 | I89: 2036.61 | J89: 244.39 | K89: Marketing Expense
A90: Total VAT on Purchases (Goods) | F90: 111591.18 | G90: 0 | H90: 124982.15 | I90: 111591.18 | J90: 13390.97
A92: Total | F92: 115365.18 | G92: 0 | H92: 128756.15 | I92: 115365.18 | J92: 13390.97

Sheet Q1 Amendment
A1: Account Transactions
A2: Shirefolk Ventures, Inc.
A3: For the period 1 January 2025 to 31 March 2025
A5: Source contains Adjustment, Bank Transfer, Conversion Balance Journal, Expense Claim, Expense Claim Payment, Manual Journal, Payable Credit Note, Payable Credit Note Allocation, Payable Credit Note Refund, Payable Invoice, Payable Overpayment, Payable Overpayment Allocation, Payable Overpayment Refund, Payable Payment, Payable Prepayment, Payable Prepayment Allocation, Payable Prepayment Refund, Receivable Credit Note, Receivable Credit Note Allocation, Receivable Credit Note Refund, Receivable Invoice, Receivable Overpayment, Receivable Overpayment Allocation, Receivable Overpayment Refund, Receivable Payment, Receivable Prepayment, Receivable Prepayment Refund, Receive Money, Spend Money
A6: Tax Rate Name contains VAT on Sales (Services), Zero Rated Sales (Services), Non-Tax, Tax Exempt
A8: Date | B8: Source | C8: Contact | D8: Description | E8: Reference | F8: Debit | G8: Credit | H8: Gross | I8: Tax | J8: Tax Rate | K8: Account
A10: Tax Exempt
A11: 45659 | B11: Receive Money | C11: Judicial Advocacy Law Firm | D11: Judicial Advocacy Law Firm - VO Balance initial deposit | F11: 0 | G11: 24000 | H11: 24000 | I11: 0 | J11: 0 | K11: Monthly Membership: Virtual Office with 10 Day Pass
A12: 45660 | B12: Spend Money | C12: Judicial Advocacy Law Firm | D12: Judicial Advocacy Law Firm - VO Balance initial deposit- returned due to insufficient fund | F12: 24000 | G12: 0 | H12: -24000 | I12: 0 | J12: 0 | K12: Monthly Membership: Virtual Office with 10 Day Pass
A13: 45719 | B13: Receive Money | C13: Unionbank | D13: Unionbank - Interest Income Feb 2025 | F13: 0 | G13: 13.89 | H13: 13.89 | I13: 0 | J13: 0 | K13: Interest Income
A14: 45719 | B14: Spend Money | C14: Unionbank | D14: Unionbank - Interest Income Feb 2025 Final tax | F14: 2.78 | G14: 0 | H14: -2.78 | I14: 0 | J14: 0 | K14: Interest Income
A15: 45747 | B15: Spend Money | C15: Metrobank | D15: Metrobank - Interest Income Final Tax Mar 2025 | F15: 11.45 | G15: 0 | H15: -11.45 | I15: 0 | J15: 0 | K15: Interest Income
A16: 45747 | B16: Receive Money | C16: Metrobank | D16: Metrobank - Interest Income Mar 2025 | F16: 0 | G16: 57.26 | H16: 57.26 | I16: 0 | J16: 0 | K16: Interest Income
A17: Total Tax Exempt | F17: =SUM(F11:F16) -> 24014.23 | G17: =SUM(G11:G16) -> 24071.15 | H17: =SUM(H11:H16) -> 56.92 | I17: =SUM(I11:I16) -> 0
A19: VAT on Sales (Services)
A20: 45658 | B20: Receivable Invoice | C20: Galleon Sciences R&D Corporation | D20: Galleon Sciences R&D Corporation - LPOG - Virtual Office, ₱3,500.00, Jan 1, 2025 - Jan 31, 2025 | E20: INV-2320 | F20: 0 | G20: 3125 | H20: 3500 | I20: 375 | J20: 12 | K20: Monthly Membership: Virtual Office with 10 Day Pass
A21: 45658 | B21: Receivable Invoice | C21: 2911 Grand Management Consulting Services | D21: 2911 Grand Management Consulting Services - LPOG - Virtual Office Renewal, ₱1,500.00, Jan 6, 2024 - Feb 5, 2025 | E21: INV-2410 | F21: 0 | G21: 1339.29 | H21: 1500 | I21: 160.71 | J21: 12 | K21: Add Ons: Business Address Registration
A22: 45658 | B22: Receivable Invoice | C22: Acton Town Inc | D22: Acton Town Inc - LPOG - Virtual Office Renewal, ₱1,500.00, Jan 13, 2025 - Dec 31, 2025 | E22: INV-2422 | F22: 0 | G22: 16071.43 | H22: 18000 | I22: 1928.57 | J22: 12 | K22: Add Ons: Business Address Registration
A23: 45658 | B23: Receivable Invoice | C23: Gesegnet Holdings Inc | D23: Gesegnet Holdings Inc - LPOG - Virtual Office Renewal, ₱1,500.00, Jan 1, 2025 - Dec 31, 2025 | E23: INV-2424 | F23: 0 | G23: 16071.43 | H23: 18000 | I23: 1928.57 | J23: 12 | K23: Add Ons: Business Address Registration
A24: 45658 | B24: Receivable Invoice | C24: Innoprince Inc. | D24: Innoprince Inc. - LPOG - Virtual Office Renewal, ₱1,500.00, Jan 1, 2025 - Dec 31, 2025 | E24: INV-2420 | F24: 0 | G24: 16071.43 | H24: 18000 | I24: 1928.57 | J24: 12 | K24: Add Ons: Business Address Registration
A25: 45658 | B25: Receivable Invoice | C25: Judicial Advocacy Law Firm | D25: Judicial Advocacy Law Firm - LPOG - Virtual Office, ₱4,000.00, Jan 1, 2025 - Jun 30, 2025 | E25: INV-2463 | F25: 0 | G25: 21428.57 | H25: 24000 | I25: 2571.43 | J25: 12 | K25: Monthly Membership: Virtual Office with 10 Day Pass
A26: 45658 | B26: Receivable Invoice | C26: Mereb Realty | D26: Mereb Realty - LPOG - Locker Rental, ₱300.00, Dec 9, 2024 - Jan 8, 2025 | E26: INV-2392 | F26: 0 | G26: 267.86 | H26: 300 | I26: 32.14 | J26: 12 | K26: Add Ons: Locker Rental
A27: 45658 | B27: Receivable Invoice | C27: Mereb Realty | D27: Mereb Realty - LPOG - Locker Rental, ₱300.00, Jan 9, 2025 - Feb 8, 2025 | E27: INV-2521 | F27: 0 | G27: 267.86 | H27: 300 | I27: 32.14 | J27: 12 | K27: Add Ons: Locker Rental
A28: 45658 | B28: Receivable Invoice | C28: Mereb Realty | D28: Mereb Realty - LPOG - Virtual Office, ₱4,000.00, Jan 16, 2025 - Feb 15, 2025 | E28: INV-2522 | F28: 0 | G28: 3571.43 | H28: 4000 | I28: 428.57 | J28: 12 | K28: Monthly Membership: Virtual Office with 10 Day Pass
A29: 45658 | B29: Receivable Invoice | C29: QBE Group Shared Services Ltd- Philippine Branch | D29: QBE Group Shared Services Ltd- Philippine Branch - 10% of PRIVATE OFFICE RENTAL with VAT | E29: INV-2393 | F29: 0 | G29: 175560 | H29: 196627.2 | I29: 21067.2 | J29: 12 | K29: Monthly Membership: Private Office
A30: 45658 | B30: Receivable Invoice | C30: QBE Group Shared Services Ltd- Philippine Branch | D30: QBE Group Shared Services Ltd- Philippine Branch - 10% of PRIVATE OFFICE RENTAL with VAT | E30: INV-2393 | F30: 0 | G30: 1562.79 | H30: 1750.32 | I30: 187.53 | J30: 12 | K30: Other Revenue from Clients
A31: 45658 | B31: Receivable Invoice | C31: Rapha Jirei Holdings Inc | D31: Rapha Jirei Holdings Inc - LPOG - Virtual Office Renewal, ₱1,500.00, Jan 1, 2025 - Dec 31, 2025 | E31: INV-2423 | F31: 0 | G31: 16071.43 | H31: 18000 | I31: 1928.57 | J31: 12 | K31: Add Ons: Business Address Registration
... A248: 45746 | B248: Receivable Invoice | C248: Feast Bellevue PM | D248: Feast Bellevue PM - LPOG - Basic PA system | E248: INV-2549 | F248: 0 | G248: 892.86 | H248: 1000 | I248: 107.14 | J248: 12 | K248: Events: Equipment Rental
A249: Total VAT on Sales (Services) | F249: =SUM(F20:F248) -> 0 | G249: =SUM(G20:G248) -> 1468889.2 | H249: =SUM(H20:H248) -> 1645155.9 | I249: =SUM(I20:I248) -> 176266.71
D250: REPORTED IN Q4 2024
A251: 45658 | B251: Receivable Invoice | C251: Galleon Sciences R&D Corporation | D251: Galleon Sciences R&D Corporation - LPOG - Virtual Office, ₱3,500.00, Jan 1, 2025 - Jan 31, 2025 | E251: INV-2320 | F251: 0 | G251: 3125 | H251: 3500 | I251: 375 | J251: 12 | K251: Monthly Membership: Virtual Office with 10 Day Pass
A252: 45689 | B252: Receivable Invoice | C252: Galleon Sciences R&D Corporation | D252: Galleon Sciences R&D Corporation - LPOG - Virtual Office, ₱3,500.00, Feb 1, 2025 - Feb 28, 2025 | E252: INV-2321 | F252: 0 | G252: 3125 | H252: 3500 | I252: 375 | J252: 12 | K252: Monthly Membership: Virtual Office with 10 Day Pass
A253: 45658 | B253: Receivable Invoice | C253: 2911 Grand Management Consulting Services | D253: 2911 Grand Management Consulting Services - LPOG - Virtual Office Renewal, ₱1,500.00, Jan 6, 2024 - Feb 5, 2025 | E253: INV-2410 | F253: 0 | G253: 1339.29 | H253: 1500 | I253: 160.71 | J253: 12 | K253: Add Ons: Business Address Registration
A254: 45658 | B254: Receivable Invoice | C254: Innoprince Inc. | D254: Innoprince Inc. - LPOG - Virtual Office Renewal, ₱1,500.00, Jan 1, 2025 - Dec 31, 2025 | E254: INV-2420 | F254: 0 | G254: 16071.43 | H254: 18000 | I254: 1928.57 | J254: 12 | K254: Add Ons: Business Address Registration
A255: 45658 | B255: Receivable Invoice | C255: Sw7 Solagratia Inc | D255: Sw7 Solagratia Inc - LPOG - Virtual Office Renewal, ₱1,500.00, Jan 1, 2025 - Dec 31, 2025 | E255: INV-2421 | F255: 0 | G255: 16071.43 | H255: 18000 | I255: 1928.57 | J255: 12 | K255: Add Ons: Business Address Registration
